Workbook
Name TRANSMUTATION_TABLE: #REF!

Sheet Instructions
A1: Use short (8.5 X 11 board paper)

Sheet Class Info
A2: Names | B2: LRN | C2: Sex | D2: Age | E2: Q1 BEHAVIOR | F2: Q2 | G2: Q3 | H2: Q4
A3: Antonio Reyes | B3: 123456789012 | C3: MALE | D3: 10
A4: Carlo Dela Cruz | B4: 123456789012 | C4: MALE | D4: 10
A5: Daniel Bautista | B5: 123456789012 | C5: MALE | D5: 11
A6: Ernesto Garcia | B6: 123456789012 | C6: MALE | D6: 10
A7: Joseph Mendoza | B7: 123456789012 | C7: MALE | D7: 10
A8: Luis Fernandez | B8: 123456789012 | C8: MALE | D8: 10
A9: Miguel Santos | B9: 123456789012 | C9: MALE | D9: 10
A10: Paolo Navarro | B10: 123456789012 | C10: MALE | D10: 10
A11: Rafael Castillo | B11: 123456789012 | C11: MALE | D11: 10
A12: Ramon Villanueva | B12: 123456789012 | C12: MALE | D12: 10

Sheet K-12 Front
P1: Republic of the Philippines
A2: REPORT ON ATTENDANCE | P2: DEPARTMENT OF EDUCATION
P3: National Capital Region
B4: June | C4: July | D4: August | E4: September | F4: October | G4: November | H4: December | I4: January | J4: February | K4: March | N4: Total | P4: Division of Parañaque City
P5: 2nd District
P6: STO. NIÑO ELEMENTARY SCHOOL
P7: School ID : 123456
A9: No. of school days | B9: 10 | C9: 10 | D9: 10 | E9: 10 | F9: 10 | G9: 10 | H9: 10 | I9: 10 | J9: 10 | K9: 10 | N9: =SUM(B9:M11) -> 100 | P9: LEARNER'S PROGRESS REPORT CARD
A12: No. of days present | B12: =B9-B15 -> 9 | C12: =C9-C15 -> 8 | D12: =D9-D15 -> 10 | E12: =E9-E15 -> 9 | F12: =F9-F15 -> 9 | G12: =G9-G15 -> 10 | H12: =H9-H15 -> 9 | I12: =I9-I15 -> 8 | ... K12: =K9-K15 -> 9 | N12: =SUM(B12:M14) -> 90 | P12: Name: | Q12: Carlo Dela Cruz
P13: Age: | Q13: =VLOOKUP(Q12,'Class Info'!A3:D49,COLUMN('Class Info'!D:D)-COLUMN('Class Info'!A3:D49)+1,0) -> 10 | T13: Sex: | U13: =VLOOKUP(Q12,'Class Info'!A3:D49,COLUMN('Class Info'!C:C)-COLUMN('Class Info'!A3:D49)+1,0) -> MALE | W13: LRN: | X13: =VLOOKUP(Q12,'Class Info'!A3:D49,COLUMN('Class Info'!B:B)-COLUMN('Class Info'!A3:D49)+1,0) -> 123456789012
P14: Grade: | R14: FIVE | T14: Section: | V14: RIZAL
A15: No. of days absent | B15: 1 | C15: 2 | D15: 0 | E15: 1 | F15: 1 | G15: 0 | H15: 1 | I15: 2 | J15: 1 | K15: 1 | N15: =SUM(B15:M17) -> 10 | P15: School Year: | R15: 2025-2026
P17: Dear Parent:
Q18: This report card shows the ability and progress your child has
P19: made in the different learning areas as well as his/her core values.
Q20: The school welcomes you if you desire to know more about your
P21: child's progress.
A22: PARENT'S/GUARDIAN'S SIGNATURE | V22: JUAN DELA CRUZ
A24: 1st QUARTER | V24: Teacher
Q25: ADRES BONIFACO
A26: 2nd QUARTER | Q26: Principal
A28: 3rd QUARTER | P28: Certificate of Transfer
P29: Admitted to Grade: | T29: FIVE | W29: Section: | Y29: RIZAL
A30: 4th QUARTER | P30: Eligibility for Admission to Grade:
V32: JUAN DELA CRUZ
P34: Approved: | V34: Teacher
Q35: ANDRES BONIFACIO
Q36: Principal
P38: Cancellation of Eligibility to Transfer
P39: Admitted in:
P40: Date:
V42: Principal

Sheet Grade 5 Inside
A1: REPORT ON LEARNING PROGRESS AND ACHIEVEMENT | I1: REPORT ON LEARNER'S OBSERVED VALUES
A3: Learning Areas | B3: QUARTER | F3: Final | G3: Remarks | I3: Core Values | K3: Behavior Statements | P3: QUARTER
B4: 1 | C4: 2 | D4: 3 | E4: 4 | F4: Grade | P4: 1 | Q4: 2 | R4: 3 | S4: 4
A5: Filipino | B5: =VLOOKUP(U5,'QUARTER 1 GRADES'!B3:O53,COLUMN('QUARTER 1 GRADES'!G:G)-COLUMN('QUARTER 1 GRADES'!B3:R53)+1,0) -> 77 | C5: =VLOOKUP(U5,'QUARTER 2 GRADES'!B3:O54,COLUMN('QUARTER 2 GRADES'!G:G)-COLUMN('QUARTER 2 GRADES'!B3:Q54)+1,0) -> 78 | D5: =VLOOKUP(U5,'QUARTER 3 GRADES'!B3:O53,COLUMN('QUARTER 3 GRADES'!G:G)-COLUMN('QUARTER 3 GRADES'!B3:R53)+1,0) -> 84 | E5: =VLOOKUP(U5,'QUARTER 4 GRADES'!B3:O53,COLUMN('QUARTER 4 GRADES'!G:G)-COLUMN('QUARTER 4 GRADES'!B3:Q53)+1,0) -> 84 | F5: =ROUND(AVERAGE(B5:E6),0) -> 81 | G5: Passed | K5: Expresses one's spiritual beliefs while respecting the spiritual beliefs of others. | P5: AO | Q5: =P5 -> AO | R5: =Q5 -> AO | S5: =R5 -> AO | U5: Ernesto Garcia
A7: English | B7: =VLOOKUP(U5,'QUARTER 1 GRADES'!B3:O53,COLUMN('QUARTER 1 GRADES'!D:D)-COLUMN('QUARTER 1 GRADES'!B3:R53)+1,0) -> 78 | C7: =VLOOKUP(U5,'QUARTER 2 GRADES'!B3:O54,COLUMN('QUARTER 2 GRADES'!D:D)-COLUMN('QUARTER 2 GRADES'!B3:Q54)+1,0) -> 80 | D7: =VLOOKUP(U5,'QUARTER 3 GRADES'!B3:O53,COLUMN('QUARTER 2 GRADES'!D:D)-COLUMN('QUARTER 3 GRADES'!B3:R53)+1,0) -> 80 | E7: =VLOOKUP(U5,'QUARTER 4 GRADES'!B3:O53,COLUMN('QUARTER 4 GRADES'!D:D)-COLUMN('QUARTER 4 GRADES'!B3:Q53)+1,0) -> 80 | F7: =ROUND(AVERAGE(B7:E8),0) -> 80 | G7: Passed | I7: 1. Maka-
I8: Diyos
A9: Mathematics | B9: =VLOOKUP(U5,'QUARTER 1 GRADES'!B3:O53,COLUMN('QUARTER 1 GRADES'!E:E)-COLUMN('QUARTER 1 GRADES'!B3:R53)+1,0) -> 79 | C9: =VLOOKUP(U5,'QUARTER 2 GRADES'!B3:O54,COLUMN('QUARTER 2 GRADES'!E:E)-COLUMN('QUARTER 2 GRADES'!B3:Q54)+1,0) -> 80 | D9: =VLOOKUP(U5,'QUARTER 3 GRADES'!B3:O53,COLUMN('QUARTER 2 GRADES'!E:E)-COLUMN('QUARTER 3 GRADES'!B3:R53)+1,0) -> 78 | E9: =VLOOKUP(U5,'QUARTER 4 GRADES'!B3:O53,COLUMN('QUARTER 4 GRADES'!E:E)-COLUMN('QUARTER 4 GRADES'!B3:Q53)+1,0) -> 81 | F9: =ROUND(AVERAGE(B9:E10),0) -> 80 | G9: Passed | K9: Shows adherence to ethical principles by upholding truth | P9: =P5 -> AO | Q9: =$Q$5 -> AO | R9: =$Q$5 -> AO | S9: =$Q$5 -> AO
A11: Science | B11: =VLOOKUP(U5,'QUARTER 1 GRADES'!B3:O53,COLUMN('QUARTER 1 GRADES'!F:F)-COLUMN('QUARTER 1 GRADES'!B3:R53)+1,0) -> 77 | C11: =VLOOKUP(U5,'QUARTER 2 GRADES'!B3:O54,COLUMN('QUARTER 2 GRADES'!F:F)-COLUMN('QUARTER 2 GRADES'!B3:Q54)+1,0) -> 80 | D11: =VLOOKUP(U5,'QUARTER 3 GRADES'!B3:O53,COLUMN('QUARTER 2 GRADES'!F:F)-COLUMN('QUARTER 3 GRADES'!B3:R53)+1,0) -> 77 | E11: =VLOOKUP(U5,'QUARTER 4 GRADES'!B3:O53,COLUMN('QUARTER 4 GRADES'!F:F)-COLUMN('QUARTER 4 GRADES'!B3:Q53)+1,0) -> 81 | F11: =ROUND(AVERAGE(B11:E12),0) -> 79 | G11: Passed
I12: 2. Makatao | K12: Is sensitive to individual, social and cultural differences | P12: =$P$5 -> AO | Q12: =$Q$5 -> AO | R12: =$Q$5 -> AO | S12: =$Q$5 -> AO
A13: Good Manners & Right Conduct (GMRC) | B13: =VLOOKUP(U5,'QUARTER 1 GRADES'!B3:O53,COLUMN('QUARTER 1 GRADES'!C:C)-COLUMN('QUARTER 1 GRADES'!B3:R53)+1,0) -> 81 | C13: =VLOOKUP(U5,'QUARTER 2 GRADES'!B3:O54,COLUMN('QUARTER 2 GRADES'!C:C)-COLUMN('QUARTER 2 GRADES'!B3:Q54)+1,0) -> 84 | D13: =VLOOKUP(U5,'QUARTER 3 GRADES'!B3:O53,COLUMN('QUARTER 2 GRADES'!C:C)-COLUMN('QUARTER 3 GRADES'!B3:R53)+1,0) -> 85 | E13: =VLOOKUP(U5,'QUARTER 4 GRADES'!B3:O53,COLUMN('QUARTER 4 GRADES'!C:C)-COLUMN('QUARTER 4 GRADES'!B3:Q53)+1,0) -> 87 | F13: =ROUND(AVERAGE(B13:E15),0) -> 84 | G13: Passed
K15: Demonstrates constributions toward solidarity | P15: =$P$5 -> AO | Q15: =$Q$5 -> AO | R15: =$Q$5 -> AO | S15: =$Q$5 -> AO
A16: Araling Panlipunan (AP) | B16: =VLOOKUP(U5,'QUARTER 1 GRADES'!B3:O53,COLUMN('QUARTER 1 GRADES'!H:H)-COLUMN('QUARTER 1 GRADES'!B3:R53)+1,0) -> 80 | C16: =VLOOKUP(U5,'QUARTER 2 GRADES'!B3:O54,COLUMN('QUARTER 2 GRADES'!H:H)-COLUMN('QUARTER 2 GRADES'!B3:Q54)+1,0) -> 81 | D16: =VLOOKUP(U5,'QUARTER 3 GRADES'!B3:O53,COLUMN('QUARTER 2 GRADES'!H:H)-COLUMN('QUARTER 3 GRADES'!B3:R53)+1,0) -> 81 | E16: =VLOOKUP(U5,'QUARTER 4 GRADES'!B3:O53,COLUMN('QUARTER 4 GRADES'!H:H)-COLUMN('QUARTER 4 GRADES'!B3:Q53)+1,0) -> 83 | F16: =ROUND(AVERAGE(B16:E18),0) -> 81 | G16: Passed
I18: 3. Maka- | K18: Cares for the environment and utilizes resources wisely, judiciously, and economically | P18: =$P$5 -> AO | Q18: =$Q$5 -> AO | R18: =$Q$5 -> AO | S18: =$Q$5 -> AO
A19: Edukasyong Pantahanan at Pangkabuhayan (EPP) | B19: =VLOOKUP(U5,'QUARTER 1 GRADES'!B3:O53,COLUMN('QUARTER 1 GRADES'!I:I)-COLUMN('QUARTER 1 GRADES'!B3:R53)+1,0) -> 84 | C19: =VLOOKUP(U5,'QUARTER 2 GRADES'!B3:O54,COLUMN('QUARTER 2 GRADES'!I:I)-COLUMN('QUARTER 2 GRADES'!B3:Q54)+1,0) -> 85 | D19: =VLOOKUP(U5,'QUARTER 3 GRADES'!B3:O53,COLUMN('QUARTER 2 GRADES'!I:I)-COLUMN('QUARTER 3 GRADES'!B3:R53)+1,0) -> 86 | E19: =VLOOKUP(U5,'QUARTER 4 GRADES'!B3:O53,COLUMN('QUARTER 4 GRADES'!I:I)-COLUMN('QUARTER 4 GRADES'!B3:Q53)+1,0) -> 88 | F19: =ROUND(AVERAGE(B19:E21),0) -> 86 | G19: Passed | I19: kalikasan
I21: 4. Maka- | K21: Demonstrates pride in being a Filipino; exercises the rights and responsibilities of a Filipino citizen | P21: =P18 -> AO | Q21: =Q18 -> AO | R21: =R18 -> AO | S21: =S18 -> AO
A22: MAPEH | B22: =VLOOKUP(U5,'QUARTER 1 GRADES'!B3:O53,COLUMN('QUARTER 1 GRADES'!J:J)-COLUMN('QUARTER 1 GRADES'!B3:R53)+1,0) -> 84 | C22: =VLOOKUP(U5,'QUARTER 2 GRADES'!B3:O54,COLUMN('QUARTER 2 GRADES'!J:J)-COLUMN('QUARTER 2 GRADES'!B3:Q54)+1,0) -> 85 | D22: =VLOOKUP(U5,'QUARTER 3 GRADES'!B3:O53,COLUMN('QUARTER 2 GRADES'!J:J)-COLUMN('QUARTER 3 GRADES'!B3:R53)+1,0) -> 84 | E22: =VLOOKUP(U5,'QUARTER 4 GRADES'!B3:O53,COLUMN('QUARTER 4 GRADES'!J:J)-COLUMN('QUARTER 4 GRADES'!B3:Q53)+1,0) -> 86 | F22: =ROUND(AVERAGE(B22:E22),0) -> 85 | G22: Passed
A23: Music & Arts | B23: =VLOOKUP(U5,'QUARTER 1 GRADES'!B3:O53,COLUMN('QUARTER 1 GRADES'!K:K)-COLUMN('QUARTER 1 GRADES'!B3:R53)+1,0) -> 84 | C23: =VLOOKUP(U5,'QUARTER 2 GRADES'!B3:O54,COLUMN('QUARTER 2 GRADES'!K:K)-COLUMN('QUARTER 2 GRADES'!B3:Q54)+1,0) -> 84 | D23: =VLOOKUP(U5,'QUARTER 3 GRADES'!B3:O53,COLUMN('QUARTER 2 GRADES'!K:K)-COLUMN('QUARTER 3 GRADES'!B3:R53)+1,0) -> 83 | E23: =VLOOKUP(U5,'QUARTER 4 GRADES'!B3:O53,COLUMN('QUARTER 4 GRADES'!K:K)-COLUMN('QUARTER 4 GRADES'!B3:Q53)+1,0) -> 85 | F23: =ROUND(AVERAGE(B23:E23),0) -> 84 | G23: Passed
A24: PE & Health | B24: =VLOOKUP(U5,'QUARTER 1 GRADES'!B3:O53,COLUMN('QUARTER 1 GRADES'!L:L)-COLUMN('QUARTER 1 GRADES'!B3:R53)+1,0) -> 84 | C24: =VLOOKUP(U5,'QUARTER 2 GRADES'!B3:O54,COLUMN('QUARTER 2 GRADES'!L:L)-COLUMN('QUARTER 2 GRADES'!B3:Q54)+1,0) -> 85 | D24: =VLOOKUP(U5,'QUARTER 3 GRADES'!B3:O53,COLUMN('QUARTER 2 GRADES'!L:L)-COLUMN('QUARTER 3 GRADES'!B3:R53)+1,0) -> 84 | E24: =VLOOKUP(U5,'QUARTER 4 GRADES'!B3:O53,COLUMN('QUARTER 4 GRADES'!L:L)-COLUMN('QUARTER 4 GRADES'!B3:Q53)+1,0) -> 86 | F24: =ROUND(AVERAGE(B24:E24),0) -> 85 | G24: Passed
B25: =AVERAGE(B5:B22) -> 80 | C25: =AVERAGE(C5:C22) -> 81.625 | D25: =AVERAGE(D5:D22) -> 81.875 | E25: =AVERAGE(E5:E22) -> 83.75 | F25: =ROUND(AVERAGE(B25:E25),0) -> 82 | G25: Passed | I25: bansa | K25: Demonstrates appropriate behavior in carrying out activities in the school, community, and country | P25: =P21 -> AO | Q25: =Q21 -> AO | R25: =R21 -> AO | S25: =S21 -> AO
A26: AVERAGE | B26: =ROUND(B25,0) -> 80 | C26: =ROUND(C25,0) -> 82 | D26: =ROUND(D25,0) -> 82 | E26: =ROUND(E25,0) -> 84 | F26: =ROUND(AVERAGE(B26:E26),0) -> 82 | G26: Passed
B27: General Average | F27: =ROUND(AVERAGE(F5:F22),0) -> 82
C28: Q1 | D28: Q2 | E28: Q3 | F28: Q4
A29: Learning Modality | C29: F2F | D29: F2F | E29: F2F | F29: F2F
A31: Description | D31: Grading Scale | F31: Remarks | J31: Marking | N31: Non-numerical Rating
A32: Outstanding | D32: 90-100 | F32: Passed | J32: AO | O32: Always Observed
A33: Very Satisfactory | D33: 85-89 | F33: Passed | J33: SO | O33: Sometimes Observed
A34: Satisfactory | D34: 80-84 | F34: Passed | J34: RO | O34: Rarely Observed
A35: Fairly Satisfactory | D35: 75-79 | F35: Passed | J35: NO | O35: Not Observed
A36: Did Not Meet Expectations | D36: Below 75 | F36: Failed

Sheet QUARTER 1 GRADES
B1: LEARNERS' NAMES | C1: GMRC | D1: ENGLISH | E1: MATH | F1: SCIENCE | G1: FILIPINO | H1: ARALING PANLIPUNAN | I1: EPP | J1: MAPEH | O1: AVERAGE | Q1: RANKING
C2: 1 | D2: 2 | E2: 3 | F2: 4 | G2: 5 | H2: 6 | I2: 7 | J2: 8 | K2: Music Arts | L2: PE Health
A3: 1 | B3: Antonio Reyes | C3: 85 | D3: 81 | E3: 81 | F3: 78 | G3: 80 | H3: 84 | I3: 86 | J3: 83 | K3: 83 | L3: 83 | O3: =ROUND(P3,0) -> 82 | P3: =SUM(C3:J3)/8 -> 82.25 | Q3: =RANK(P3,$P$3:$P$43) -> 3
A4: 2 | B4: Carlo Dela Cruz | C4: 82 | D4: 80 | E4: 83 | F4: 79 | G4: 79 | H4: 80 | I4: 84 | J4: 85 | K4: 83 | L4: 86 | O4: =ROUND(P4,0) -> 82 | P4: =SUM(C4:J4)/8 -> 81.5 | Q4: =RANK(P4,$P$3:$P$43) -> 4
A5: 3 | B5: Daniel Bautista | C5: 81 | D5: 83 | E5: 80 | F5: 76 | G5: 82 | H5: 79 | I5: 80 | J5: 81 | K5: 80 | L5: 81 | O5: =ROUND(P5,0) -> 80 | P5: =SUM(C5:J5)/8 -> 80.25 | Q5: =RANK(P5,$P$3:$P$43) -> 7
A6: 4 | B6: Ernesto Garcia | C6: 81 | D6: 78 | E6: 79 | F6: 77 | G6: 77 | H6: 80 | I6: 84 | J6: 84 | K6: 84 | L6: 84 | O6: =ROUND(P6,0) -> 80 | P6: =SUM(C6:J6)/8 -> 80 | Q6: =RANK(P6,$P$3:$P$43) -> 8
A7: 5 | B7: Joseph Mendoza | C7: 85 | D7: 82 | E7: 84 | F7: 79 | G7: 81 | H7: 80 | I7: 84 | J7: 86 | K7: 85 | L7: 86 | O7: =ROUND(P7,0) -> 83 | P7: =SUM(C7:J7)/8 -> 82.625 | Q7: =RANK(P7,$P$3:$P$43) -> 2
A8: 6 | B8: Luis Fernandez | C8: 83 | D8: 77 | E8: 80 | F8: 77 | G8: 76 | H8: 83 | I8: 84 | J8: 85 | K8: 85 | L8: 84 | O8: =ROUND(P8,0) -> 81 | P8: =SUM(C8:J8)/8 -> 80.625 | Q8: =RANK(P8,$P$3:$P$43) -> 6
A9: 7 | B9: Miguel Santos | C9: 89 | D9: 88 | E9: 82 | F9: 82 | G9: 87 | H9: 89 | I9: 90 | J9: 89 | K9: 89 | L9: 88 | O9: =ROUND(P9,0) -> 87 | P9: =SUM(C9:J9)/8 -> 87 | Q9: =RANK(P9,$P$3:$P$43) -> 1
A10: 8 | B10: Paolo Navarro | C10: 81 | D10: 80 | E10: 83 | F10: 80 | G10: 80 | H10: 80 | I10: 82 | J10: 81 | K10: 82 | L10: 80 | O10: =ROUND(P10,0) -> 81 | P10: =SUM(C10:J10)/8 -> 80.875 | Q10: =RANK(P10,$P$3:$P$43) -> 5
A11: 9 | B11: Rafael Castillo | C11: 80 | D11: 79 | E11: 77 | F11: 76 | G11: 79 | H11: 77 | I11: 79 | J11: 78 | K11: 78 | L11: 78 | O11: =ROUND(P11,0) -> 78 | P11: =SUM(C11:J11)/8 -> 78.125 | Q11: =RANK(P11,$P$3:$P$43) -> 9
A12: 10 | B12: Ramon Villanueva | C12: 80 | D12: 77 | E12: 76 | F12: 75 | G12: 77 | H12: 78 | I12: 80 | J12: 78 | K12: 77 | L12: 79 | O12: =ROUND(P12,0) -> 78 | P12: =SUM(C12:J12)/8 -> 77.625 | Q12: =RANK(P12,$P$3:$P$43) -> 10
A13: 11 | O13: =ROUND(P13,0) -> 0 | P13: =SUM(C13:J13)/8 -> 0 | Q13: =RANK(P13,$P$3:$P$43) -> 11
A14: 12 | O14: =ROUND(P14,0) -> 0 | P14: =SUM(C14:J14)/8 -> 0 | Q14: =RANK(P14,$P$3:$P$43) -> 11
A15: 13 | O15: =ROUND(P15,0) -> 0 | P15: =SUM(C15:J15)/8 -> 0 | Q15: =RANK(P15,$P$3:$P$43) -> 11
A16: 14 | O16: =ROUND(P16,0) -> 0 | P16: =SUM(C16:J16)/8 -> 0 | Q16: =RANK(P16,$P$3:$P$43) -> 11
A17: 15 | O17: =ROUND(P17,0) -> 0 | P17: =SUM(C17:J17)/8 -> 0 | Q17: =RANK(P17,$P$3:$P$43) -> 11
A18: 16 | O18: =ROUND(P18,0) -> 0 | P18: =SUM(C18:J18)/8 -> 0 | Q18: =RANK(P18,$P$3:$P$43) -> 11
A19: 17 | O19: =ROUND(P19,0) -> 0 | P19: =SUM(C19:J19)/8 -> 0 | Q19: =RANK(P19,$P$3:$P$43) -> 11
A20: 18 | O20: =ROUND(P20,0) -> 0 | P20: =SUM(C20:J20)/8 -> 0 | Q20: =RANK(P20,$P$3:$P$43) -> 11
A21: 19 | O21: =ROUND(P21,0) -> 0 | P21: =SUM(C21:J21)/8 -> 0 | Q21: =RANK(P21,$P$3:$P$43) -> 11
A22: 20 | O22: =ROUND(P22,0) -> 0 | P22: =SUM(C22:J22)/8 -> 0 | Q22: =RANK(P22,$P$3:$P$43) -> 11
A23: 21 | O23: =ROUND(P23,0) -> 0 | P23: =SUM(C23:J23)/8 -> 0 | Q23: =RANK(P23,$P$3:$P$43) -> 11
A24: 22 | O24: =ROUND(P24,0) -> 0 | P24: =SUM(C24:J24)/8 -> 0 | Q24: =RANK(P24,$P$3:$P$43) -> 11
... A43: 41 | O43: =ROUND(P43,0) -> 0 | P43: =SUM(C43:J43)/8 -> 0 | Q43: =RANK(P43,$P$3:$P$43) -> 11

Sheet QUARTER 2 GRADES
B1: LEARNERS' NAMES | C1: ESP | D1: ENGLISH | E1: MATH | F1: SCIENCE | G1: FILIPINO | H1: ARALING PANLIPUNAN | I1: EPP | J1: MAPEH | O1: AVERAGE | Q1: RANKING
C2: 1 | D2: 2 | E2: 3 | F2: 4 | G2: 5 | H2: 6 | I2: 7 | J2: 8 | K2: MUSIC | L2: ARTS | M2: P.E. | N2: HEALTH
A3: 1 | B3: Antonio Reyes | C3: 86 | D3: 82 | E3: 81 | F3: 81 | G3: 81 | H3: 84 | I3: 88 | J3: 84 | K3: 84 | L3: 84 | O3: =ROUND(P3,0) -> 83 | P3: =SUM(C3:J3)/8 -> 83.375 | Q3: =RANK(P3,$P$3:$P$34) -> 3
A4: 2 | B4: Carlo Dela Cruz | C4: 84 | D4: 82 | E4: 82 | F4: 82 | G4: 80 | H4: 82 | I4: 85 | J4: 85 | K4: 84 | L4: 85 | O4: =ROUND(P4,0) -> 83 | P4: =SUM(C4:J4)/8 -> 82.75 | Q4: =RANK(P4,$P$3:$P$34) -> 4
A5: 3 | B5: Daniel Bautista | C5: 83 | D5: 84 | E5: 85 | F5: 82 | G5: 83 | H5: 81 | I5: 80 | J5: 82 | K5: 81 | L5: 82 | O5: =ROUND(P5,0) -> 83 | P5: =SUM(C5:J5)/8 -> 82.5 | Q5: =RANK(P5,$P$3:$P$34) -> 5
A6: 4 | B6: Ernesto Garcia | C6: 84 | D6: 80 | E6: 80 | F6: 80 | G6: 78 | H6: 81 | I6: 85 | J6: 85 | K6: 84 | L6: 85 | O6: =ROUND(P6,0) -> 82 | P6: =SUM(C6:J6)/8 -> 81.625 | Q6: =RANK(P6,$P$3:$P$34) -> 7
A7: 5 | B7: Joseph Mendoza | C7: 85 | D7: 83 | E7: 83 | F7: 84 | G7: 82 | H7: 82 | I7: 85 | J7: 86 | K7: 86 | L7: 86 | O7: =ROUND(P7,0) -> 84 | P7: =SUM(C7:J7)/8 -> 83.75 | Q7: =RANK(P7,$P$3:$P$34) -> 2
A8: 6 | B8: Luis Fernandez | C8: 85 | D8: 78 | E8: 80 | F8: 83 | G8: 77 | H8: 84 | I8: 84 | J8: 85 | K8: 85 | L8: 85 | O8: =ROUND(P8,0) -> 82 | P8: =SUM(C8:J8)/8 -> 82 | Q8: =RANK(P8,$P$3:$P$34) -> 6
A9: 7 | B9: Miguel Santos | C9: 90 | D9: 89 | E9: 84 | F9: 82 | G9: 88 | H9: 89 | I9: 88 | J9: 89 | K9: 89 | L9: 89 | O9: =ROUND(P9,0) -> 87 | P9: =SUM(C9:J9)/8 -> 87.375 | Q9: =RANK(P9,$P$3:$P$34) -> 1
A10: 8 | B10: Paolo Navarro | C10: 83 | D10: 81 | E10: 81 | F10: 83 | G10: 80 | H10: 81 | I10: 82 | J10: 82 | K10: 82 | L10: 81 | O10: =ROUND(P10,0) -> 82 | P10: =SUM(C10:J10)/8 -> 81.625 | Q10: =RANK(P10,$P$3:$P$34) -> 7
A11: 9 | B11: Rafael Castillo | C11: 82 | D11: 80 | E11: 84 | F11: 83 | G11: 79 | H11: 77 | I11: 79 | J11: 80 | K11: 79 | L11: 80 | O11: =ROUND(P11,0) -> 81 | P11: =SUM(C11:J11)/8 -> 80.5 | Q11: =RANK(P11,$P$3:$P$34) -> 9
A12: 10 | B12: Ramon Villanueva | C12: 82 | D12: 78 | E12: 78 | F12: 78 | G12: 77 | H12: 79 | I12: 80 | J12: 79 | K12: 78 | L12: 79 | O12: =ROUND(P12,0) -> 79 | P12: =SUM(C12:J12)/8 -> 78.875 | Q12: =RANK(P12,$P$3:$P$34) -> 10
A13: 11 | O13: =ROUND(P13,0) -> 0 | P13: =SUM(C13:J13)/8 -> 0 | Q13: =RANK(P13,$P$3:$P$34) -> 11
A14: 12 | O14: =ROUND(P14,0) -> 0 | P14: =SUM(C14:J14)/8 -> 0 | Q14: =RANK(P14,$P$3:$P$34) -> 11
A15: 13 | O15: =ROUND(P15,0) -> 0 | P15: =SUM(C15:J15)/8 -> 0 | Q15: =RANK(P15,$P$3:$P$34) -> 11
A16: 14 | O16: =ROUND(P16,0) -> 0 | P16: =SUM(C16:J16)/8 -> 0 | Q16: =RANK(P16,$P$3:$P$34) -> 11
A17: 15 | O17: =ROUND(P17,0) -> 0 | P17: =SUM(C17:J17)/8 -> 0 | Q17: =RANK(P17,$P$3:$P$34) -> 11
A18: 16 | O18: =ROUND(P18,0) -> 0 | P18: =SUM(C18:J18)/8 -> 0 | Q18: =RANK(P18,$P$3:$P$34) -> 11
A19: 17 | O19: =ROUND(P19,0) -> 0 | P19: =SUM(C19:J19)/8 -> 0 | Q19: =RANK(P19,$P$3:$P$34) -> 11
A20: 18 | O20: =ROUND(P20,0) -> 0 | P20: =SUM(C20:J20)/8 -> 0 | Q20: =RANK(P20,$P$3:$P$34) -> 11
A21: 19 | O21: =ROUND(P21,0) -> 0 | P21: =SUM(C21:J21)/8 -> 0 | Q21: =RANK(P21,$P$3:$P$34) -> 11
A22: 20 | O22: =ROUND(P22,0) -> 0 | P22: =SUM(C22:J22)/8 -> 0 | Q22: =RANK(P22,$P$3:$P$34) -> 11
A23: 21 | O23: =ROUND(P23,0) -> 0 | P23: =SUM(C23:J23)/8 -> 0 | Q23: =RANK(P23,$P$3:$P$34) -> 11
A24: 22 | O24: =ROUND(P24,0) -> 0 | P24: =SUM(C24:J24)/8 -> 0 | Q24: =RANK(P24,$P$3:$P$34) -> 11
... A34: 32 | O34: =ROUND(P34,0) -> 0 | P34: =SUM(C34:J34)/8 -> 0 | Q34: =RANK(P34,$P$3:$P$34) -> 11
A35: 33 | O35: =ROUND(P35,0) -> 0 | P35: =SUM(C35:J35)/8 -> 0 | Q35: =RANK(P35,$P$3:$P$35) -> 11
A36: 34 | O36: =ROUND(P36,0) -> 0 | P36: =SUM(C36:J36)/8 -> 0 | Q36: =RANK(P36,$P$3:$P$43) -> 11
A37: 35 | O37: =ROUND(P37,0) -> 0 | P37: =SUM(C37:J37)/8 -> 0 | Q37: =RANK(P37,$P$3:$P$43) -> 11
A38: 36 | O38: =ROUND(P38,0) -> 0 | P38: =SUM(C38:J38)/8 -> 0 | Q38: =RANK(P38,$P$3:$P$43) -> 11
A39: 37 | O39: =ROUND(P39,0) -> 0 | P39: =SUM(C39:J39)/8 -> 0 | Q39: =RANK(P39,$P$3:$P$43) -> 11
A40: 38 | O40: =ROUND(P40,0) -> 0 | P40: =SUM(C40:J40)/8 -> 0 | Q40: =RANK(P40,$P$3:$P$43) -> 11
A41: 39 | O41: =ROUND(P41,0) -> 0 | P41: =SUM(C41:J41)/8 -> 0 | Q41: =RANK(P41,$P$3:$P$43) -> 11
A42: 40 | O42: =ROUND(P42,0) -> 0 | P42: =SUM(C42:J42)/8 -> 0 | Q42: =RANK(P42,$P$3:$P$43) -> 11
A43: 41 | O43: =ROUND(P43,0) -> 0 | P43: =SUM(C43:J43)/8 -> 0 | Q43: =RANK(P43,$P$3:$P$43) -> 11

Sheet QUARTER 3 GRADES
B1: LEARNERS' NAMES | C1: ESP | D1: ENGLISH | E1: MATH | F1: SCIENCE | G1: FILIPINO | H1: ARALING PANLIPUNAN | I1: EPP | J1: MAPEH | O1: AVERAGE | Q1: RANKING
C2: 1 | D2: 2 | E2: 3 | F2: 4 | G2: 5 | H2: 6 | I2: 7 | J2: 8 | K2: MUSIC | L2: ARTS | M2: P.E. | N2: HEALTH
A3: 1 | B3: Antonio Reyes | C3: 87 | D3: 81 | E3: 80 | F3: 80 | G3: 81 | H3: 86 | I3: 89 | J3: 85 | K3: 85 | L3: 84 | O3: =ROUND(P3,0) -> 84 | P3: =SUM(C3:J3)/8 -> 83.625 | Q3: =RANK(P3,$P$3:$P$34) -> 3
A4: 2 | B4: Carlo Dela Cruz | C4: 85 | D4: 81 | E4: 80 | F4: 80 | G4: 81 | H4: 83 | I4: 87 | J4: 85 | K4: 84 | L4: 85 | O4: =ROUND(P4,0) -> 83 | P4: =SUM(C4:J4)/8 -> 82.75 | Q4: =RANK(P4,$P$3:$P$34) -> 5
A5: 3 | B5: Daniel Bautista | C5: 84 | D5: 84 | E5: 83 | F5: 82 | G5: 85 | H5: 82 | I5: 82 | J5: 81 | K5: 80 | L5: 81 | O5: =ROUND(P5,0) -> 83 | P5: =SUM(C5:J5)/8 -> 82.875 | Q5: =RANK(P5,$P$3:$P$34) -> 4
A6: 4 | B6: Ernesto Garcia | C6: 85 | D6: 80 | E6: 78 | F6: 77 | G6: 84 | H6: 81 | I6: 86 | J6: 84 | K6: 83 | L6: 84 | O6: =ROUND(P6,0) -> 82 | P6: =SUM(C6:J6)/8 -> 81.875 | Q6: =RANK(P6,$P$3:$P$34) -> 7
A7: 5 | B7: Joseph Mendoza | C7: 87 | D7: 83 | E7: 82 | F7: 80 | G7: 83 | H7: 83 | I7: 86 | J7: 86 | K7: 86 | L7: 86 | O7: =ROUND(P7,0) -> 84 | P7: =SUM(C7:J7)/8 -> 83.75 | Q7: =RANK(P7,$P$3:$P$34) -> 2
A8: 6 | B8: Luis Fernandez | C8: 86 | D8: 78 | E8: 79 | F8: 81 | G8: 80 | H8: 85 | I8: 85 | J8: 85 | K8: 85 | L8: 85 | O8: =ROUND(P8,0) -> 82 | P8: =SUM(C8:J8)/8 -> 82.375 | Q8: =RANK(P8,$P$3:$P$34) -> 6
A9: 7 | B9: Miguel Santos | C9: 91 | D9: 87 | E9: 82 | F9: 83 | G9: 86 | H9: 90 | I9: 90 | J9: 89 | K9: 89 | L9: 89 | O9: =ROUND(P9,0) -> 87 | P9: =SUM(C9:J9)/8 -> 87.25 | Q9: =RANK(P9,$P$3:$P$34) -> 1
A10: 8 | B10: Paolo Navarro | O10: =ROUND(P10,0) -> 0 | P10: =SUM(C10:J10)/8 -> 0 | Q10: =RANK(P10,$P$3:$P$34) -> 10
A11: 9 | B11: Rafael Castillo | C11: 83 | D11: 80 | E11: 80 | F11: 81 | G11: 82 | H11: 78 | I11: 81 | J11: 79 | K11: 78 | L11: 80 | O11: =ROUND(P11,0) -> 81 | P11: =SUM(C11:J11)/8 -> 80.5 | Q11: =RANK(P11,$P$3:$P$34) -> 8
A12: 10 | B12: Ramon Villanueva | C12: 83 | D12: 78 | E12: 78 | F12: 80 | G12: 81 | H12: 79 | I12: 82 | J12: 79 | K12: 78 | L12: 79 | O12: =ROUND(P12,0) -> 80 | P12: =SUM(C12:J12)/8 -> 80 | Q12: =RANK(P12,$P$3:$P$34) -> 9
A13: 11 | O13: =ROUND(P13,0) -> 0 | P13: =SUM(C13:J13)/8 -> 0 | Q13: =RANK(P13,$P$3:$P$34) -> 10
A14: 12 | O14: =ROUND(P14,0) -> 0 | P14: =SUM(C14:J14)/8 -> 0 | Q14: =RANK(P14,$P$3:$P$34) -> 10
A15: 13 | O15: =ROUND(P15,0) -> 0 | P15: =SUM(C15:J15)/8 -> 0 | Q15: =RANK(P15,$P$3:$P$34) -> 10
A16: 14 | O16: =ROUND(P16,0) -> 0 | P16: =SUM(C16:J16)/8 -> 0 | Q16: =RANK(P16,$P$3:$P$34) -> 10
A17: 15 | O17: =ROUND(P17,0) -> 0 | P17: =SUM(C17:J17)/8 -> 0 | Q17: =RANK(P17,$P$3:$P$34) -> 10
A18: 16 | O18: =ROUND(P18,0) -> 0 | P18: =SUM(C18:J18)/8 -> 0 | Q18: =RANK(P18,$P$3:$P$34) -> 10
A19: 17 | O19: =ROUND(P19,0) -> 0 | P19: =SUM(C19:J19)/8 -> 0 | Q19: =RANK(P19,$P$3:$P$34) -> 10
A20: 18 | O20: =ROUND(P20,0) -> 0 | P20: =SUM(C20:J20)/8 -> 0 | Q20: =RANK(P20,$P$3:$P$34) -> 10
A21: 19 | O21: =ROUND(P21,0) -> 0 | P21: =SUM(C21:J21)/8 -> 0 | Q21: =RANK(P21,$P$3:$P$34) -> 10
A22: 20 | O22: =ROUND(P22,0) -> 0 | P22: =SUM(C22:J22)/8 -> 0 | Q22: =RANK(P22,$P$3:$P$34) -> 10
A23: 21 | O23: =ROUND(P23,0) -> 0 | P23: =SUM(C23:J23)/8 -> 0 | Q23: =RANK(P23,$P$3:$P$34) -> 10
A24: 22 | O24: =ROUND(P24,0) -> 0 | P24: =SUM(C24:J24)/8 -> 0 | Q24: =RANK(P24,$P$3:$P$34) -> 10
... A34: 32 | O34: =ROUND(P34,0) -> 0 | P34: =SUM(C34:J34)/8 -> 0 | Q34: =RANK(P34,$P$3:$P$34) -> 10
A35: 33 | O35: =ROUND(P35,0) -> 0 | P35: =SUM(C35:J35)/8 -> 0 | Q35: =RANK(P35,$P$3:$P$35) -> 10
A36: 34 | O36: =ROUND(P36,0) -> 0 | P36: =SUM(C36:J36)/8 -> 0 | Q36: =RANK(P36,$P$3:$P$43) -> 10
A37: 35 | O37: =ROUND(P37,0) -> 0 | P37: =SUM(C37:J37)/8 -> 0 | Q37: =RANK(P37,$P$3:$P$43) -> 10
A38: 36 | O38: =ROUND(P38,0) -> 0 | P38: =SUM(C38:J38)/8 -> 0 | Q38: =RANK(P38,$P$3:$P$43) -> 10
A39: 37 | O39: =ROUND(P39,0) -> 0 | P39: =SUM(C39:J39)/8 -> 0 | Q39: =RANK(P39,$P$3:$P$43) -> 10
A40: 38 | O40: =ROUND(P40,0) -> 0 | P40: =SUM(C40:J40)/8 -> 0 | Q40: =RANK(P40,$P$3:$P$43) -> 10
A41: 39 | O41: =ROUND(P41,0) -> 0 | P41: =SUM(C41:J41)/8 -> 0 | Q41: =RANK(P41,$P$3:$P$43) -> 10
A42: 40 | O42: =ROUND(P42,0) -> 0 | P42: =SUM(C42:J42)/8 -> 0 | Q42: =RANK(P42,$P$3:$P$43) -> 10
A43: 41 | O43: =ROUND(P43,0) -> 0 | P43: =SUM(C43:J43)/8 -> 0 | Q43: =RANK(P43,$P$3:$P$43) -> 10

Sheet QUARTER 4 GRADES
B1: LEARNERS' NAMES | C1: ESP | D1: ENGLISH | E1: MATH | F1: SCIENCE | G1: FILIPINO | H1: ARALING PANLIPUNAN | I1: EPP | J1: MAPEH | O1: AVERAGE | Q1: RANKING
C2: 1 | D2: 2 | E2: 3 | F2: 4 | G2: 5 | H2: 6 | I2: 7 | J2: 8 | K2: MUSIC | L2: ARTS | M2: P.E. | N2: HEALTH
A3: 1 | B3: Antonio Reyes | C3: 88 | D3: 81 | E3: 81 | F3: 80 | G3: 81 | H3: 87 | I3: 90 | J3: 86 | K3: 87 | L3: 85 | O3: =ROUND(P3,0) -> 84 | P3: =SUM(C3:J3)/8 -> 84.25 | Q3: =RANK(P3,$P$3:$P$34) -> 4
A4: 2 | B4: Carlo Dela Cruz | C4: 86 | D4: 81 | E4: 86 | F4: 85 | G4: 81 | H4: 85 | I4: 88 | J4: 86 | K4: 85 | L4: 86 | O4: =ROUND(P4,0) -> 85 | P4: =SUM(C4:J4)/8 -> 84.75 | Q4: =RANK(P4,$P$3:$P$34) -> 2
A5: 3 | B5: Daniel Bautista | C5: 85 | D5: 84 | E5: 81 | F5: 81 | G5: 85 | H5: 84 | I5: 85 | J5: 83 | K5: 82 | L5: 83 | O5: =ROUND(P5,0) -> 84 | P5: =SUM(C5:J5)/8 -> 83.5 | Q5: =RANK(P5,$P$3:$P$34) -> 6
A6: 4 | B6: Ernesto Garcia | C6: 87 | D6: 80 | E6: 81 | F6: 81 | G6: 84 | H6: 83 | I6: 88 | J6: 86 | K6: 85 | L6: 86 | O6: =ROUND(P6,0) -> 84 | P6: =SUM(C6:J6)/8 -> 83.75 | Q6: =RANK(P6,$P$3:$P$34) -> 5
A7: 5 | B7: Joseph Mendoza | C7: 88 | D7: 83 | E7: 83 | F7: 81 | G7: 83 | H7: 84 | I7: 87 | J7: 87 | K7: 87 | L7: 87 | O7: =ROUND(P7,0) -> 85 | P7: =SUM(C7:J7)/8 -> 84.5 | Q7: =RANK(P7,$P$3:$P$34) -> 3
A8: 6 | B8: Luis Fernandez | C8: 86 | D8: 78 | E8: 80 | F8: 80 | G8: 80 | H8: 87 | I8: 86 | J8: 86 | K8: 86 | L8: 86 | O8: =ROUND(P8,0) -> 83 | P8: =SUM(C8:J8)/8 -> 82.875 | Q8: =RANK(P8,$P$3:$P$34) -> 7
A9: 7 | B9: Miguel Santos | C9: 92 | D9: 87 | E9: 85 | F9: 85 | G9: 86 | H9: 91 | I9: 91 | J9: 90 | K9: 90 | L9: 90 | O9: =ROUND(P9,0) -> 88 | P9: =SUM(C9:J9)/8 -> 88.375 | Q9: =RANK(P9,$P$3:$P$34) -> 1
A10: 8 | B10: Paolo Navarro | O10: =ROUND(P10,0) -> 0 | P10: =SUM(C10:J10)/8 -> 0 | Q10: =RANK(P10,$P$3:$P$34) -> 10
A11: 9 | B11: Rafael Castillo | C11: 85 | D11: 80 | E11: 80 | F11: 80 | G11: 82 | H11: 81 | I11: 83 | J11: 81 | K11: 80 | L11: 82 | O11: =ROUND(P11,0) -> 82 | P11: =SUM(C11:J11)/8 -> 81.5 | Q11: =RANK(P11,$P$3:$P$34) -> 8
A12: 10 | B12: Ramon Villanueva | C12: 85 | D12: 78 | E12: 80 | F12: 82 | G12: 81 | H12: 81 | I12: 84 | J12: 80 | K12: 80 | L12: 80 | O12: =ROUND(P12,0) -> 81 | P12: =SUM(C12:J12)/8 -> 81.375 | Q12: =RANK(P12,$P$3:$P$34) -> 9
A13: 11 | O13: =ROUND(P13,0) -> 0 | P13: =SUM(C13:J13)/8 -> 0 | Q13: =RANK(P13,$P$3:$P$34) -> 10
A14: 12 | O14: =ROUND(P14,0) -> 0 | P14: =SUM(C14:J14)/8 -> 0 | Q14: =RANK(P14,$P$3:$P$34) -> 10
A15: 13 | O15: =ROUND(P15,0) -> 0 | P15: =SUM(C15:J15)/8 -> 0 | Q15: =RANK(P15,$P$3:$P$34) -> 10
A16: 14 | O16: =ROUND(P16,0) -> 0 | P16: =SUM(C16:J16)/8 -> 0 | Q16: =RANK(P16,$P$3:$P$34) -> 10
A17: 15 | O17: =ROUND(P17,0) -> 0 | P17: =SUM(C17:J17)/8 -> 0 | Q17: =RANK(P17,$P$3:$P$34) -> 10
A18: 16 | O18: =ROUND(P18,0) -> 0 | P18: =SUM(C18:J18)/8 -> 0 | Q18: =RANK(P18,$P$3:$P$34) -> 10
A19: 17 | O19: =ROUND(P19,0) -> 0 | P19: =SUM(C19:J19)/8 -> 0 | Q19: =RANK(P19,$P$3:$P$34) -> 10
A20: 18 | O20: =ROUND(P20,0) -> 0 | P20: =SUM(C20:J20)/8 -> 0 | Q20: =RANK(P20,$P$3:$P$34) -> 10
A21: 19 | O21: =ROUND(P21,0) -> 0 | P21: =SUM(C21:J21)/8 -> 0 | Q21: =RANK(P21,$P$3:$P$34) -> 10
A22: 20 | O22: =ROUND(P22,0) -> 0 | P22: =SUM(C22:J22)/8 -> 0 | Q22: =RANK(P22,$P$3:$P$34) -> 10
A23: 21 | O23: =ROUND(P23,0) -> 0 | P23: =SUM(C23:J23)/8 -> 0 | Q23: =RANK(P23,$P$3:$P$34) -> 10
A24: 22 | O24: =ROUND(P24,0) -> 0 | P24: =SUM(C24:J24)/8 -> 0 | Q24: =RANK(P24,$P$3:$P$34) -> 10
... A34: 32 | O34: =ROUND(P34,0) -> 0 | P34: =SUM(C34:J34)/8 -> 0 | Q34: =RANK(P34,$P$3:$P$34) -> 10
A35: 33 | O35: =ROUND(P35,0) -> 0 | P35: =SUM(C35:J35)/8 -> 0 | Q35: =RANK(P35,$P$3:$P$35) -> 10
A36: 34 | O36: =ROUND(P36,0) -> 0 | P36: =SUM(C36:J36)/8 -> 0 | Q36: =RANK(P36,$P$3:$P$43) -> 10
A37: 35 | O37: =ROUND(P37,0) -> 0 | P37: =SUM(C37:J37)/8 -> 0 | Q37: =RANK(P37,$P$3:$P$43) -> 10
A38: 36 | O38: =ROUND(P38,0) -> 0 | P38: =SUM(C38:J38)/8 -> 0 | Q38: =RANK(P38,$P$3:$P$43) -> 10
A39: 37 | O39: =ROUND(P39,0) -> 0 | P39: =SUM(C39:J39)/8 -> 0 | Q39: =RANK(P39,$P$3:$P$43) -> 10
A40: 38 | O40: =ROUND(P40,0) -> 0 | P40: =SUM(C40:J40)/8 -> 0 | Q40: =RANK(P40,$P$3:$P$43) -> 10
A41: 39 | O41: =ROUND(P41,0) -> 0 | P41: =SUM(C41:J41)/8 -> 0 | Q41: =RANK(P41,$P$3:$P$43) -> 10
A42: 40 | O42: =ROUND(P42,0) -> 0 | P42: =SUM(C42:J42)/8 -> 0 | Q42: =RANK(P42,$P$3:$P$43) -> 10
A43: 41 | O43: =ROUND(P43,0) -> 0 | P43: =SUM(C43:J43)/8 -> 0 | Q43: =RANK(P43,$P$3:$P$43) -> 10

Sheet FINAL SUMMARY
B1: FINAL GRADES AND GENERAL AVERAGE
C3: REGION | G3: NCR | R3: DIVISION | AE3: SCHOOL YEAR | AK3: 2025-2026
C5: SCHOOL NAME | G5: STO. NIÑO ELEMENTARY SCHOOL | R5: SCHOOL ID | U5: 123456 | AE5: GRADE & SECTION | AK5: V-RIZAL
A7: NAMES OF LEARNERS | F7: FLIPINO | K7: ENGLISH | P7: MATHEMATICS | U7: SCIENCE | Z7: AP | AE7: EPP | AJ7: MAPEH | AO7: ESP | AU7: Gen. Average
F8: QUARTER | J8: FINAL GRADE | K8: QUARTER | O8: FINAL GRADE | P8: QUARTER | T8: FINAL GRADE | U8: QUARTER | Y8: FINAL GRADE | Z8: QUARTER | AD8: FINAL GRADE | AE8: QUARTER | AI8: FINAL GRADE | AJ8: QUARTER | AN8: FINAL GRADE | AO8: QUARTER | AS8: FINAL GRADE
F9: 1 | G9: 2 | H9: 3 | I9: 4 | K9: 1 | L9: 2 | M9: 3 | N9: 4 | P9: 1 | Q9: 2 | R9: 3 | S9: 4 | U9: 1 | V9: 2 | W9: 3 | X9: 4 | Z9: 1 | AA9: 2 | AB9: 3 | AC9: 4 | AE9: 1 | AF9: 2 | AG9: 3 | AH9: 4 | AJ9: 1 | AK9: 2 | AL9: 3 | AM9: 4 | AO9: 1 | AP9: 2 | AQ9: 3 | AR9: 4
B10: MALE
A11: 1 | B11: Antonio Reyes | J11: =IF(OR(F11="",G11="",H11="",I11=""),"",IF(ISERROR(ROUND(AVERAGE(F11,G11,H11,I11),0)),"",ROUND(AVERAGE(F11,G11,H11,I11),0))) | O11: =IF(OR(K11="",L11="",M11="",N11=""),"",IF(ISERROR(ROUND(AVERAGE(K11,L11,M11,N11),0)),"",ROUND(AVERAGE(K11,L11,M11,N11),0))) | T11: =IF(OR(P11="",Q11="",R11="",S11=""),"",IF(ISERROR(ROUND(AVERAGE(P11,Q11,R11,S11),0)),"",ROUND(AVERAGE(P11,Q11,R11,S11),0))) | Y11: =IF(OR(U11="",V11="",W11="",X11=""),"",IF(ISERROR(ROUND(AVERAGE(U11,V11,W11,X11),0)),"",ROUND(AVERAGE(U11,V11,W11,X11),0))) | AD11: =IF(OR(Z11="",AA11="",AB11="",AC11=""),"",IF(ISERROR(ROUND(AVERAGE(Z11,AA11,AB11,AC11),0)),"",ROUND(AVERAGE(Z11,AA11,AB11,AC11),0))) | AI11: =IF(OR(AE11="",AF11="",AG11="",AH11=""),"",IF(ISERROR(ROUND(AVERAGE(AE11,AF11,AG11,AH11),0)),"",ROUND(AVERAGE(AE11,AF11,AG11,AH11),0))) | AN11: =IF(OR(AJ11="",AK11="",AL11="",AM11=""),"",IF(ISERROR(ROUND(AVERAGE(AJ11,AK11,AL11,AM11),0)),"",ROUND(AVERAGE(AJ11,AK11,AL11,AM11),0))) | AS11: =IF(OR(AO11="",AP11="",AQ11="",AR11=""),"",IF(ISERROR(ROUND(AVERAGE(AO11,AP11,AQ11,AR11),0)),"",ROUND(AVERAGE(AO11,AP11,AQ11,AR11),0))) | AT11: =IF(ISERROR(J11+O11+T11+Y11+AD11+AI11+AN11+AS11)/8,"",(J11+O11+T11+Y11+AD11+AI11+AN11+AS11)/8) -> 0 | AU11: =IF(ISERROR(ROUND(AT11,0)),"",ROUND(AT11,0)) -> 0
A12: 2 | B12: Carlo Dela Cruz | J12: =IF(OR(F12="",G12="",H12="",I12=""),"",IF(ISERROR(ROUND(AVERAGE(F12,G12,H12,I12),0)),"",ROUND(AVERAGE(F12,G12,H12,I12),0))) | O12: =IF(OR(K12="",L12="",M12="",N12=""),"",IF(ISERROR(ROUND(AVERAGE(K12,L12,M12,N12),0)),"",ROUND(AVERAGE(K12,L12,M12,N12),0))) | T12: =IF(OR(P12="",Q12="",R12="",S12=""),"",IF(ISERROR(ROUND(AVERAGE(P12,Q12,R12,S12),0)),"",ROUND(AVERAGE(P12,Q12,R12,S12),0))) | Y12: =IF(OR(U12="",V12="",W12="",X12=""),"",IF(ISERROR(ROUND(AVERAGE(U12,V12,W12,X12),0)),"",ROUND(AVERAGE(U12,V12,W12,X12),0))) | AD12: =IF(OR(Z12="",AA12="",AB12="",AC12=""),"",IF(ISERROR(ROUND(AVERAGE(Z12,AA12,AB12,AC12),0)),"",ROUND(AVERAGE(Z12,AA12,AB12,AC12),0))) | AI12: =IF(OR(AE12="",AF12="",AG12="",AH12=""),"",IF(ISERROR(ROUND(AVERAGE(AE12,AF12,AG12,AH12),0)),"",ROUND(AVERAGE(AE12,AF12,AG12,AH12),0))) | AN12: =IF(OR(AJ12="",AK12="",AL12="",AM12=""),"",IF(ISERROR(ROUND(AVERAGE(AJ12,AK12,AL12,AM12),0)),"",ROUND(AVERAGE(AJ12,AK12,AL12,AM12),0))) | AS12: =IF(OR(AO12="",AP12="",AQ12="",AR12=""),"",IF(ISERROR(ROUND(AVERAGE(AO12,AP12,AQ12,AR12),0)),"",ROUND(AVERAGE(AO12,AP12,AQ12,AR12),0))) | AT12: =IF(ISERROR(J12+O12+T12+Y12+AD12+AI12+AN12+AS12)/8,"",(J12+O12+T12+Y12+AD12+AI12+AN12+AS12)/8) -> 0 | AU12: =IF(ISERROR(ROUND(AT12,0)),"",ROUND(AT12,0)) -> 0
A13: 3 | B13: Daniel Bautista | J13: =IF(OR(F13="",G13="",H13="",I13=""),"",IF(ISERROR(ROUND(AVERAGE(F13,G13,H13,I13),0)),"",ROUND(AVERAGE(F13,G13,H13,I13),0))) | O13: =IF(OR(K13="",L13="",M13="",N13=""),"",IF(ISERROR(ROUND(AVERAGE(K13,L13,M13,N13),0)),"",ROUND(AVERAGE(K13,L13,M13,N13),0))) | T13: =IF(OR(P13="",Q13="",R13="",S13=""),"",IF(ISERROR(ROUND(AVERAGE(P13,Q13,R13,S13),0)),"",ROUND(AVERAGE(P13,Q13,R13,S13),0))) | Y13: =IF(OR(U13="",V13="",W13="",X13=""),"",IF(ISERROR(ROUND(AVERAGE(U13,V13,W13,X13),0)),"",ROUND(AVERAGE(U13,V13,W13,X13),0))) | AD13: =IF(OR(Z13="",AA13="",AB13="",AC13=""),"",IF(ISERROR(ROUND(AVERAGE(Z13,AA13,AB13,AC13),0)),"",ROUND(AVERAGE(Z13,AA13,AB13,AC13),0))) | AI13: =IF(OR(AE13="",AF13="",AG13="",AH13=""),"",IF(ISERROR(ROUND(AVERAGE(AE13,AF13,AG13,AH13),0)),"",ROUND(AVERAGE(AE13,AF13,AG13,AH13),0))) | AN13: =IF(OR(AJ13="",AK13="",AL13="",AM13=""),"",IF(ISERROR(ROUND(AVERAGE(AJ13,AK13,AL13,AM13),0)),"",ROUND(AVERAGE(AJ13,AK13,AL13,AM13),0))) | AS13: =IF(OR(AO13="",AP13="",AQ13="",AR13=""),"",IF(ISERROR(ROUND(AVERAGE(AO13,AP13,AQ13,AR13),0)),"",ROUND(AVERAGE(AO13,AP13,AQ13,AR13),0))) | AT13: =IF(ISERROR(J13+O13+T13+Y13+AD13+AI13+AN13+AS13)/8,"",(J13+O13+T13+Y13+AD13+AI13+AN13+AS13)/8) -> 0 | AU13: =IF(ISERROR(ROUND(AT13,0)),"",ROUND(AT13,0)) -> 0
A14: 4 | B14: Ernesto Garcia | J14: =IF(OR(F14="",G14="",H14="",I14=""),"",IF(ISERROR(ROUND(AVERAGE(F14,G14,H14,I14),0)),"",ROUND(AVERAGE(F14,G14,H14,I14),0))) | O14: =IF(OR(K14="",L14="",M14="",N14=""),"",IF(ISERROR(ROUND(AVERAGE(K14,L14,M14,N14),0)),"",ROUND(AVERAGE(K14,L14,M14,N14),0))) | T14: =IF(OR(P14="",Q14="",R14="",S14=""),"",IF(ISERROR(ROUND(AVERAGE(P14,Q14,R14,S14),0)),"",ROUND(AVERAGE(P14,Q14,R14,S14),0))) | Y14: =IF(OR(U14="",V14="",W14="",X14=""),"",IF(ISERROR(ROUND(AVERAGE(U14,V14,W14,X14),0)),"",ROUND(AVERAGE(U14,V14,W14,X14),0))) | AD14: =IF(OR(Z14="",AA14="",AB14="",AC14=""),"",IF(ISERROR(ROUND(AVERAGE(Z14,AA14,AB14,AC14),0)),"",ROUND(AVERAGE(Z14,AA14,AB14,AC14),0))) | AI14: =IF(OR(AE14="",AF14="",AG14="",AH14=""),"",IF(ISERROR(ROUND(AVERAGE(AE14,AF14,AG14,AH14),0)),"",ROUND(AVERAGE(AE14,AF14,AG14,AH14),0))) | AN14: =IF(OR(AJ14="",AK14="",AL14="",AM14=""),"",IF(ISERROR(ROUND(AVERAGE(AJ14,AK14,AL14,AM14),0)),"",ROUND(AVERAGE(AJ14,AK14,AL14,AM14),0))) | AS14: =IF(OR(AO14="",AP14="",AQ14="",AR14=""),"",IF(ISERROR(ROUND(AVERAGE(AO14,AP14,AQ14,AR14),0)),"",ROUND(AVERAGE(AO14,AP14,AQ14,AR14),0))) | AT14: =IF(ISERROR(J14+O14+T14+Y14+AD14+AI14+AN14+AS14)/8,"",(J14+O14+T14+Y14+AD14+AI14+AN14+AS14)/8) -> 0 | AU14: =IF(ISERROR(ROUND(AT14,0)),"",ROUND(AT14,0)) -> 0
A15: 5 | B15: Joseph Mendoza | J15: =IF(OR(F15="",G15="",H15="",I15=""),"",IF(ISERROR(ROUND(AVERAGE(F15,G15,H15,I15),0)),"",ROUND(AVERAGE(F15,G15,H15,I15),0))) | O15: =IF(OR(K15="",L15="",M15="",N15=""),"",IF(ISERROR(ROUND(AVERAGE(K15,L15,M15,N15),0)),"",ROUND(AVERAGE(K15,L15,M15,N15),0))) | T15: =IF(OR(P15="",Q15="",R15="",S15=""),"",IF(ISERROR(ROUND(AVERAGE(P15,Q15,R15,S15),0)),"",ROUND(AVERAGE(P15,Q15,R15,S15),0))) | Y15: =IF(OR(U15="",V15="",W15="",X15=""),"",IF(ISERROR(ROUND(AVERAGE(U15,V15,W15,X15),0)),"",ROUND(AVERAGE(U15,V15,W15,X15),0))) | AD15: =IF(OR(Z15="",AA15="",AB15="",AC15=""),"",IF(ISERROR(ROUND(AVERAGE(Z15,AA15,AB15,AC15),0)),"",ROUND(AVERAGE(Z15,AA15,AB15,AC15),0))) | AI15: =IF(OR(AE15="",AF15="",AG15="",AH15=""),"",IF(ISERROR(ROUND(AVERAGE(AE15,AF15,AG15,AH15),0)),"",ROUND(AVERAGE(AE15,AF15,AG15,AH15),0))) | AN15: =IF(OR(AJ15="",AK15="",AL15="",AM15=""),"",IF(ISERROR(ROUND(AVERAGE(AJ15,AK15,AL15,AM15),0)),"",ROUND(AVERAGE(AJ15,AK15,AL15,AM15),0))) | AS15: =IF(OR(AO15="",AP15="",AQ15="",AR15=""),"",IF(ISERROR(ROUND(AVERAGE(AO15,AP15,AQ15,AR15),0)),"",ROUND(AVERAGE(AO15,AP15,AQ15,AR15),0))) | AT15: =IF(ISERROR(J15+O15+T15+Y15+AD15+AI15+AN15+AS15)/8,"",(J15+O15+T15+Y15+AD15+AI15+AN15+AS15)/8) -> 0 | AU15: =IF(ISERROR(ROUND(AT15,0)),"",ROUND(AT15,0)) -> 0
A16: 6 | B16: Luis Fernandez | J16: =IF(OR(F16="",G16="",H16="",I16=""),"",IF(ISERROR(ROUND(AVERAGE(F16,G16,H16,I16),0)),"",ROUND(AVERAGE(F16,G16,H16,I16),0))) | O16: =IF(OR(K16="",L16="",M16="",N16=""),"",IF(ISERROR(ROUND(AVERAGE(K16,L16,M16,N16),0)),"",ROUND(AVERAGE(K16,L16,M16,N16),0))) | T16: =IF(OR(P16="",Q16="",R16="",S16=""),"",IF(ISERROR(ROUND(AVERAGE(P16,Q16,R16,S16),0)),"",ROUND(AVERAGE(P16,Q16,R16,S16),0))) | Y16: =IF(OR(U16="",V16="",W16="",X16=""),"",IF(ISERROR(ROUND(AVERAGE(U16,V16,W16,X16),0)),"",ROUND(AVERAGE(U16,V16,W16,X16),0))) | AD16: =IF(OR(Z16="",AA16="",AB16="",AC16=""),"",IF(ISERROR(ROUND(AVERAGE(Z16,AA16,AB16,AC16),0)),"",ROUND(AVERAGE(Z16,AA16,AB16,AC16),0))) | AI16: =IF(OR(AE16="",AF16="",AG16="",AH16=""),"",IF(ISERROR(ROUND(AVERAGE(AE16,AF16,AG16,AH16),0)),"",ROUND(AVERAGE(AE16,AF16,AG16,AH16),0))) | AN16: =IF(OR(AJ16="",AK16="",AL16="",AM16=""),"",IF(ISERROR(ROUND(AVERAGE(AJ16,AK16,AL16,AM16),0)),"",ROUND(AVERAGE(AJ16,AK16,AL16,AM16),0))) | AS16: =IF(OR(AO16="",AP16="",AQ16="",AR16=""),"",IF(ISERROR(ROUND(AVERAGE(AO16,AP16,AQ16,AR16),0)),"",ROUND(AVERAGE(AO16,AP16,AQ16,AR16),0))) | AT16: =IF(ISERROR(J16+O16+T16+Y16+AD16+AI16+AN16+AS16)/8,"",(J16+O16+T16+Y16+AD16+AI16+AN16+AS16)/8) -> 0 | AU16: =IF(ISERROR(ROUND(AT16,0)),"",ROUND(AT16,0)) -> 0
A17: 7 | B17: Miguel Santos | J17: =IF(OR(F17="",G17="",H17="",I17=""),"",IF(ISERROR(ROUND(AVERAGE(F17,G17,H17,I17),0)),"",ROUND(AVERAGE(F17,G17,H17,I17),0))) | O17: =IF(OR(K17="",L17="",M17="",N17=""),"",IF(ISERROR(ROUND(AVERAGE(K17,L17,M17,N17),0)),"",ROUND(AVERAGE(K17,L17,M17,N17),0))) | T17: =IF(OR(P17="",Q17="",R17="",S17=""),"",IF(ISERROR(ROUND(AVERAGE(P17,Q17,R17,S17),0)),"",ROUND(AVERAGE(P17,Q17,R17,S17),0))) | Y17: =IF(OR(U17="",V17="",W17="",X17=""),"",IF(ISERROR(ROUND(AVERAGE(U17,V17,W17,X17),0)),"",ROUND(AVERAGE(U17,V17,W17,X17),0))) | AD17: =IF(OR(Z17="",AA17="",AB17="",AC17=""),"",IF(ISERROR(ROUND(AVERAGE(Z17,AA17,AB17,AC17),0)),"",ROUND(AVERAGE(Z17,AA17,AB17,AC17),0))) | AI17: =IF(OR(AE17="",AF17="",AG17="",AH17=""),"",IF(ISERROR(ROUND(AVERAGE(AE17,AF17,AG17,AH17),0)),"",ROUND(AVERAGE(AE17,AF17,AG17,AH17),0))) | AN17: =IF(OR(AJ17="",AK17="",AL17="",AM17=""),"",IF(ISERROR(ROUND(AVERAGE(AJ17,AK17,AL17,AM17),0)),"",ROUND(AVERAGE(AJ17,AK17,AL17,AM17),0))) | AS17: =IF(OR(AO17="",AP17="",AQ17="",AR17=""),"",IF(ISERROR(ROUND(AVERAGE(AO17,AP17,AQ17,AR17),0)),"",ROUND(AVERAGE(AO17,AP17,AQ17,AR17),0))) | AT17: =IF(ISERROR(J17+O17+T17+Y17+AD17+AI17+AN17+AS17)/8,"",(J17+O17+T17+Y17+AD17+AI17+AN17+AS17)/8) -> 0 | AU17: =IF(ISERROR(ROUND(AT17,0)),"",ROUND(AT17,0)) -> 0
A18: 8 | B18: Paolo Navarro | J18: =IF(OR(F18="",G18="",H18="",I18=""),"",IF(ISERROR(ROUND(AVERAGE(F18,G18,H18,I18),0)),"",ROUND(AVERAGE(F18,G18,H18,I18),0))) | O18: =IF(OR(K18="",L18="",M18="",N18=""),"",IF(ISERROR(ROUND(AVERAGE(K18,L18,M18,N18),0)),"",ROUND(AVERAGE(K18,L18,M18,N18),0))) | T18: =IF(OR(P18="",Q18="",R18="",S18=""),"",IF(ISERROR(ROUND(AVERAGE(P18,Q18,R18,S18),0)),"",ROUND(AVERAGE(P18,Q18,R18,S18),0))) | Y18: =IF(OR(U18="",V18="",W18="",X18=""),"",IF(ISERROR(ROUND(AVERAGE(U18,V18,W18,X18),0)),"",ROUND(AVERAGE(U18,V18,W18,X18),0))) | AD18: =IF(OR(Z18="",AA18="",AB18="",AC18=""),"",IF(ISERROR(ROUND(AVERAGE(Z18,AA18,AB18,AC18),0)),"",ROUND(AVERAGE(Z18,AA18,AB18,AC18),0))) | AI18: =IF(OR(AE18="",AF18="",AG18="",AH18=""),"",IF(ISERROR(ROUND(AVERAGE(AE18,AF18,AG18,AH18),0)),"",ROUND(AVERAGE(AE18,AF18,AG18,AH18),0))) | AN18: =IF(OR(AJ18="",AK18="",AL18="",AM18=""),"",IF(ISERROR(ROUND(AVERAGE(AJ18,AK18,AL18,AM18),0)),"",ROUND(AVERAGE(AJ18,AK18,AL18,AM18),0))) | AS18: =IF(OR(AO18="",AP18="",AQ18="",AR18=""),"",IF(ISERROR(ROUND(AVERAGE(AO18,AP18,AQ18,AR18),0)),"",ROUND(AVERAGE(AO18,AP18,AQ18,AR18),0))) | AT18: =IF(ISERROR(J18+O18+T18+Y18+AD18+AI18+AN18+AS18)/8,"",(J18+O18+T18+Y18+AD18+AI18+AN18+AS18)/8) -> 0 | AU18: =IF(ISERROR(ROUND(AT18,0)),"",ROUND(AT18,0)) -> 0
A19: 9 | B19: Rafael Castillo | J19: =IF(OR(F19="",G19="",H19="",I19=""),"",IF(ISERROR(ROUND(AVERAGE(F19,G19,H19,I19),0)),"",ROUND(AVERAGE(F19,G19,H19,I19),0))) | O19: =IF(OR(K19="",L19="",M19="",N19=""),"",IF(ISERROR(ROUND(AVERAGE(K19,L19,M19,N19),0)),"",ROUND(AVERAGE(K19,L19,M19,N19),0))) | T19: =IF(OR(P19="",Q19="",R19="",S19=""),"",IF(ISERROR(ROUND(AVERAGE(P19,Q19,R19,S19),0)),"",ROUND(AVERAGE(P19,Q19,R19,S19),0))) | Y19: =IF(OR(U19="",V19="",W19="",X19=""),"",IF(ISERROR(ROUND(AVERAGE(U19,V19,W19,X19),0)),"",ROUND(AVERAGE(U19,V19,W19,X19),0))) | AD19: =IF(OR(Z19="",AA19="",AB19="",AC19=""),"",IF(ISERROR(ROUND(AVERAGE(Z19,AA19,AB19,AC19),0)),"",ROUND(AVERAGE(Z19,AA19,AB19,AC19),0))) | AI19: =IF(OR(AE19="",AF19="",AG19="",AH19=""),"",IF(ISERROR(ROUND(AVERAGE(AE19,AF19,AG19,AH19),0)),"",ROUND(AVERAGE(AE19,AF19,AG19,AH19),0))) | AN19: =IF(OR(AJ19="",AK19="",AL19="",AM19=""),"",IF(ISERROR(ROUND(AVERAGE(AJ19,AK19,AL19,AM19),0)),"",ROUND(AVERAGE(AJ19,AK19,AL19,AM19),0))) | AS19: =IF(OR(AO19="",AP19="",AQ19="",AR19=""),"",IF(ISERROR(ROUND(AVERAGE(AO19,AP19,AQ19,AR19),0)),"",ROUND(AVERAGE(AO19,AP19,AQ19,AR19),0))) | AT19: =IF(ISERROR(J19+O19+T19+Y19+AD19+AI19+AN19+AS19)/8,"",(J19+O19+T19+Y19+AD19+AI19+AN19+AS19)/8) -> 0 | AU19: =IF(ISERROR(ROUND(AT19,0)),"",ROUND(AT19,0)) -> 0
A20: 10 | B20: Ramon Villanueva | J20: =IF(OR(F20="",G20="",H20="",I20=""),"",IF(ISERROR(ROUND(AVERAGE(F20,G20,H20,I20),0)),"",ROUND(AVERAGE(F20,G20,H20,I20),0))) | O20: =IF(OR(K20="",L20="",M20="",N20=""),"",IF(ISERROR(ROUND(AVERAGE(K20,L20,M20,N20),0)),"",ROUND(AVERAGE(K20,L20,M20,N20),0))) | T20: =IF(OR(P20="",Q20="",R20="",S20=""),"",IF(ISERROR(ROUND(AVERAGE(P20,Q20,R20,S20),0)),"",ROUND(AVERAGE(P20,Q20,R20,S20),0))) | Y20: =IF(OR(U20="",V20="",W20="",X20=""),"",IF(ISERROR(ROUND(AVERAGE(U20,V20,W20,X20),0)),"",ROUND(AVERAGE(U20,V20,W20,X20),0))) | AD20: =IF(OR(Z20="",AA20="",AB20="",AC20=""),"",IF(ISERROR(ROUND(AVERAGE(Z20,AA20,AB20,AC20),0)),"",ROUND(AVERAGE(Z20,AA20,AB20,AC20),0))) | AI20: =IF(OR(AE20="",AF20="",AG20="",AH20=""),"",IF(ISERROR(ROUND(AVERAGE(AE20,AF20,AG20,AH20),0)),"",ROUND(AVERAGE(AE20,AF20,AG20,AH20),0))) | AN20: =IF(OR(AJ20="",AK20="",AL20="",AM20=""),"",IF(ISERROR(ROUND(AVERAGE(AJ20,AK20,AL20,AM20),0)),"",ROUND(AVERAGE(AJ20,AK20,AL20,AM20),0))) | AS20: =IF(OR(AO20="",AP20="",AQ20="",AR20=""),"",IF(ISERROR(ROUND(AVERAGE(AO20,AP20,AQ20,AR20),0)),"",ROUND(AVERAGE(AO20,AP20,AQ20,AR20),0))) | AT20: =IF(ISERROR(J20+O20+T20+Y20+AD20+AI20+AN20+AS20)/8,"",(J20+O20+T20+Y20+AD20+AI20+AN20+AS20)/8) -> 0 | AU20: =IF(ISERROR(ROUND(AT20,0)),"",ROUND(AT20,0)) -> 0
A21: 11 | J21: =IF(OR(F21="",G21="",H21="",I21=""),"",IF(ISERROR(ROUND(AVERAGE(F21,G21,H21,I21),0)),"",ROUND(AVERAGE(F21,G21,H21,I21),0))) | O21: =IF(OR(K21="",L21="",M21="",N21=""),"",IF(ISERROR(ROUND(AVERAGE(K21,L21,M21,N21),0)),"",ROUND(AVERAGE(K21,L21,M21,N21),0))) | T21: =IF(OR(P21="",Q21="",R21="",S21=""),"",IF(ISERROR(ROUND(AVERAGE(P21,Q21,R21,S21),0)),"",ROUND(AVERAGE(P21,Q21,R21,S21),0))) | Y21: =IF(OR(U21="",V21="",W21="",X21=""),"",IF(ISERROR(ROUND(AVERAGE(U21,V21,W21,X21),0)),"",ROUND(AVERAGE(U21,V21,W21,X21),0))) | AD21: =IF(OR(Z21="",AA21="",AB21="",AC21=""),"",IF(ISERROR(ROUND(AVERAGE(Z21,AA21,AB21,AC21),0)),"",ROUND(AVERAGE(Z21,AA21,AB21,AC21),0))) | AI21: =IF(OR(AE21="",AF21="",AG21="",AH21=""),"",IF(ISERROR(ROUND(AVERAGE(AE21,AF21,AG21,AH21),0)),"",ROUND(AVERAGE(AE21,AF21,AG21,AH21),0))) | AN21: =IF(OR(AJ21="",AK21="",AL21="",AM21=""),"",IF(ISERROR(ROUND(AVERAGE(AJ21,AK21,AL21,AM21),0)),"",ROUND(AVERAGE(AJ21,AK21,AL21,AM21),0))) | AS21: =IF(OR(AO21="",AP21="",AQ21="",AR21=""),"",IF(ISERROR(ROUND(AVERAGE(AO21,AP21,AQ21,AR21),0)),"",ROUND(AVERAGE(AO21,AP21,AQ21,AR21),0))) | AT21: =IF(ISERROR(J21+O21+T21+Y21+AD21+AI21+AN21+AS21)/8,"",(J21+O21+T21+Y21+AD21+AI21+AN21+AS21)/8) -> 0 | AU21: =IF(ISERROR(ROUND(AT21,0)),"",ROUND(AT21,0)) -> 0
A22: 12 | J22: =IF(OR(F22="",G22="",H22="",I22=""),"",IF(ISERROR(ROUND(AVERAGE(F22,G22,H22,I22),0)),"",ROUND(AVERAGE(F22,G22,H22,I22),0))) | O22: =IF(OR(K22="",L22="",M22="",N22=""),"",IF(ISERROR(ROUND(AVERAGE(K22,L22,M22,N22),0)),"",ROUND(AVERAGE(K22,L22,M22,N22),0))) | T22: =IF(OR(P22="",Q22="",R22="",S22=""),"",IF(ISERROR(ROUND(AVERAGE(P22,Q22,R22,S22),0)),"",ROUND(AVERAGE(P22,Q22,R22,S22),0))) | Y22: =IF(OR(U22="",V22="",W22="",X22=""),"",IF(ISERROR(ROUND(AVERAGE(U22,V22,W22,X22),0)),"",ROUND(AVERAGE(U22,V22,W22,X22),0))) | AD22: =IF(OR(Z22="",AA22="",AB22="",AC22=""),"",IF(ISERROR(ROUND(AVERAGE(Z22,AA22,AB22,AC22),0)),"",ROUND(AVERAGE(Z22,AA22,AB22,AC22),0))) | AI22: =IF(OR(AE22="",AF22="",AG22="",AH22=""),"",IF(ISERROR(ROUND(AVERAGE(AE22,AF22,AG22,AH22),0)),"",ROUND(AVERAGE(AE22,AF22,AG22,AH22),0))) | AN22: =IF(OR(AJ22="",AK22="",AL22="",AM22=""),"",IF(ISERROR(ROUND(AVERAGE(AJ22,AK22,AL22,AM22),0)),"",ROUND(AVERAGE(AJ22,AK22,AL22,AM22),0))) | AS22: =IF(OR(AO22="",AP22="",AQ22="",AR22=""),"",IF(ISERROR(ROUND(AVERAGE(AO22,AP22,AQ22,AR22),0)),"",ROUND(AVERAGE(AO22,AP22,AQ22,AR22),0))) | AT22: =IF(ISERROR(J22+O22+T22+Y22+AD22+AI22+AN22+AS22)/8,"",(J22+O22+T22+Y22+AD22+AI22+AN22+AS22)/8) -> 0 | AU22: =IF(ISERROR(ROUND(AT22,0)),"",ROUND(AT22,0)) -> 0
A23: 13 | J23: =IF(OR(F23="",G23="",H23="",I23=""),"",IF(ISERROR(ROUND(AVERAGE(F23,G23,H23,I23),0)),"",ROUND(AVERAGE(F23,G23,H23,I23),0))) | O23: =IF(OR(K23="",L23="",M23="",N23=""),"",IF(ISERROR(ROUND(AVERAGE(K23,L23,M23,N23),0)),"",ROUND(AVERAGE(K23,L23,M23,N23),0))) | T23: =IF(OR(P23="",Q23="",R23="",S23=""),"",IF(ISERROR(ROUND(AVERAGE(P23,Q23,R23,S23),0)),"",ROUND(AVERAGE(P23,Q23,R23,S23),0))) | Y23: =IF(OR(U23="",V23="",W23="",X23=""),"",IF(ISERROR(ROUND(AVERAGE(U23,V23,W23,X23),0)),"",ROUND(AVERAGE(U23,V23,W23,X23),0))) | AD23: =IF(OR(Z23="",AA23="",AB23="",AC23=""),"",IF(ISERROR(ROUND(AVERAGE(Z23,AA23,AB23,AC23),0)),"",ROUND(AVERAGE(Z23,AA23,AB23,AC23),0))) | AI23: =IF(OR(AE23="",AF23="",AG23="",AH23=""),"",IF(ISERROR(ROUND(AVERAGE(AE23,AF23,AG23,AH23),0)),"",ROUND(AVERAGE(AE23,AF23,AG23,AH23),0))) | AN23: =IF(OR(AJ23="",AK23="",AL23="",AM23=""),"",IF(ISERROR(ROUND(AVERAGE(AJ23,AK23,AL23,AM23),0)),"",ROUND(AVERAGE(AJ23,AK23,AL23,AM23),0))) | AS23: =IF(OR(AO23="",AP23="",AQ23="",AR23=""),"",IF(ISERROR(ROUND(AVERAGE(AO23,AP23,AQ23,AR23),0)),"",ROUND(AVERAGE(AO23,AP23,AQ23,AR23),0))) | AT23: =IF(ISERROR(J23+O23+T23+Y23+AD23+AI23+AN23+AS23)/8,"",(J23+O23+T23+Y23+AD23+AI23+AN23+AS23)/8) -> 0 | AU23: =IF(ISERROR(ROUND(AT23,0)),"",ROUND(AT23,0)) -> 0
A24: 14 | J24: =IF(OR(F24="",G24="",H24="",I24=""),"",IF(ISERROR(ROUND(AVERAGE(F24,G24,H24,I24),0)),"",ROUND(AVERAGE(F24,G24,H24,I24),0))) | O24: =IF(OR(K24="",L24="",M24="",N24=""),"",IF(ISERROR(ROUND(AVERAGE(K24,L24,M24,N24),0)),"",ROUND(AVERAGE(K24,L24,M24,N24),0))) | T24: =IF(OR(P24="",Q24="",R24="",S24=""),"",IF(ISERROR(ROUND(AVERAGE(P24,Q24,R24,S24),0)),"",ROUND(AVERAGE(P24,Q24,R24,S24),0))) | Y24: =IF(OR(U24="",V24="",W24="",X24=""),"",IF(ISERROR(ROUND(AVERAGE(U24,V24,W24,X24),0)),"",ROUND(AVERAGE(U24,V24,W24,X24),0))) | AD24: =IF(OR(Z24="",AA24="",AB24="",AC24=""),"",IF(ISERROR(ROUND(AVERAGE(Z24,AA24,AB24,AC24),0)),"",ROUND(AVERAGE(Z24,AA24,AB24,AC24),0))) | AI24: =IF(OR(AE24="",AF24="",AG24="",AH24=""),"",IF(ISERROR(ROUND(AVERAGE(AE24,AF24,AG24,AH24),0)),"",ROUND(AVERAGE(AE24,AF24,AG24,AH24),0))) | AN24: =IF(OR(AJ24="",AK24="",AL24="",AM24=""),"",IF(ISERROR(ROUND(AVERAGE(AJ24,AK24,AL24,AM24),0)),"",ROUND(AVERAGE(AJ24,AK24,AL24,AM24),0))) | AS24: =IF(OR(AO24="",AP24="",AQ24="",AR24=""),"",IF(ISERROR(ROUND(AVERAGE(AO24,AP24,AQ24,AR24),0)),"",ROUND(AVERAGE(AO24,AP24,AQ24,AR24),0))) | AT24: =IF(ISERROR(J24+O24+T24+Y24+AD24+AI24+AN24+AS24)/8,"",(J24+O24+T24+Y24+AD24+AI24+AN24+AS24)/8) -> 0 | AU24: =IF(ISERROR(ROUND(AT24,0)),"",ROUND(AT24,0)) -> 0
A25: 15 | J25: =IF(OR(F25="",G25="",H25="",I25=""),"",IF(ISERROR(ROUND(AVERAGE(F25,G25,H25,I25),0)),"",ROUND(AVERAGE(F25,G25,H25,I25),0))) | O25: =IF(OR(K25="",L25="",M25="",N25=""),"",IF(ISERROR(ROUND(AVERAGE(K25,L25,M25,N25),0)),"",ROUND(AVERAGE(K25,L25,M25,N25),0))) | T25: =IF(OR(P25="",Q25="",R25="",S25=""),"",IF(ISERROR(ROUND(AVERAGE(P25,Q25,R25,S25),0)),"",ROUND(AVERAGE(P25,Q25,R25,S25),0))) | Y25: =IF(OR(U25="",V25="",W25="",X25=""),"",IF(ISERROR(ROUND(AVERAGE(U25,V25,W25,X25),0)),"",ROUND(AVERAGE(U25,V25,W25,X25),0))) | AD25: =IF(OR(Z25="",AA25="",AB25="",AC25=""),"",IF(ISERROR(ROUND(AVERAGE(Z25,AA25,AB25,AC25),0)),"",ROUND(AVERAGE(Z25,AA25,AB25,AC25),0))) | AI25: =IF(OR(AE25="",AF25="",AG25="",AH25=""),"",IF(ISERROR(ROUND(AVERAGE(AE25,AF25,AG25,AH25),0)),"",ROUND(AVERAGE(AE25,AF25,AG25,AH25),0))) | AN25: =IF(OR(AJ25="",AK25="",AL25="",AM25=""),"",IF(ISERROR(ROUND(AVERAGE(AJ25,AK25,AL25,AM25),0)),"",ROUND(AVERAGE(AJ25,AK25,AL25,AM25),0))) | AS25: =IF(OR(AO25="",AP25="",AQ25="",AR25=""),"",IF(ISERROR(ROUND(AVERAGE(AO25,AP25,AQ25,AR25),0)),"",ROUND(AVERAGE(AO25,AP25,AQ25,AR25),0))) | AT25: =IF(ISERROR(J25+O25+T25+Y25+AD25+AI25+AN25+AS25)/8,"",(J25+O25+T25+Y25+AD25+AI25+AN25+AS25)/8) -> 0 | AU25: =IF(ISERROR(ROUND(AT25,0)),"",ROUND(AT25,0)) -> 0
A26: 16 | J26: =IF(OR(F26="",G26="",H26="",I26=""),"",IF(ISERROR(ROUND(AVERAGE(F26,G26,H26,I26),0)),"",ROUND(AVERAGE(F26,G26,H26,I26),0))) | O26: =IF(OR(K26="",L26="",M26="",N26=""),"",IF(ISERROR(ROUND(AVERAGE(K26,L26,M26,N26),0)),"",ROUND(AVERAGE(K26,L26,M26,N26),0))) | T26: =IF(OR(P26="",Q26="",R26="",S26=""),"",IF(ISERROR(ROUND(AVERAGE(P26,Q26,R26,S26),0)),"",ROUND(AVERAGE(P26,Q26,R26,S26),0))) | Y26: =IF(OR(U26="",V26="",W26="",X26=""),"",IF(ISERROR(ROUND(AVERAGE(U26,V26,W26,X26),0)),"",ROUND(AVERAGE(U26,V26,W26,X26),0))) | AD26: =IF(OR(Z26="",AA26="",AB26="",AC26=""),"",IF(ISERROR(ROUND(AVERAGE(Z26,AA26,AB26,AC26),0)),"",ROUND(AVERAGE(Z26,AA26,AB26,AC26),0))) | AI26: =IF(OR(AE26="",AF26="",AG26="",AH26=""),"",IF(ISERROR(ROUND(AVERAGE(AE26,AF26,AG26,AH26),0)),"",ROUND(AVERAGE(AE26,AF26,AG26,AH26),0))) | AN26: =IF(OR(AJ26="",AK26="",AL26="",AM26=""),"",IF(ISERROR(ROUND(AVERAGE(AJ26,AK26,AL26,AM26),0)),"",ROUND(AVERAGE(AJ26,AK26,AL26,AM26),0))) | AS26: =IF(OR(AO26="",AP26="",AQ26="",AR26=""),"",IF(ISERROR(ROUND(AVERAGE(AO26,AP26,AQ26,AR26),0)),"",ROUND(AVERAGE(AO26,AP26,AQ26,AR26),0))) | AT26: =IF(ISERROR(J26+O26+T26+Y26+AD26+AI26+AN26+AS26)/8,"",(J26+O26+T26+Y26+AD26+AI26+AN26+AS26)/8) -> 0 | AU26: =IF(ISERROR(ROUND(AT26,0)),"",ROUND(AT26,0)) -> 0
A27: 17 | J27: =IF(OR(F27="",G27="",H27="",I27=""),"",IF(ISERROR(ROUND(AVERAGE(F27,G27,H27,I27),0)),"",ROUND(AVERAGE(F27,G27,H27,I27),0))) | O27: =IF(OR(K27="",L27="",M27="",N27=""),"",IF(ISERROR(ROUND(AVERAGE(K27,L27,M27,N27),0)),"",ROUND(AVERAGE(K27,L27,M27,N27),0))) | T27: =IF(OR(P27="",Q27="",R27="",S27=""),"",IF(ISERROR(ROUND(AVERAGE(P27,Q27,R27,S27),0)),"",ROUND(AVERAGE(P27,Q27,R27,S27),0))) | Y27: =IF(OR(U27="",V27="",W27="",X27=""),"",IF(ISERROR(ROUND(AVERAGE(U27,V27,W27,X27),0)),"",ROUND(AVERAGE(U27,V27,W27,X27),0))) | AD27: =IF(OR(Z27="",AA27="",AB27="",AC27=""),"",IF(ISERROR(ROUND(AVERAGE(Z27,AA27,AB27,AC27),0)),"",ROUND(AVERAGE(Z27,AA27,AB27,AC27),0))) | AI27: =IF(OR(AE27="",AF27="",AG27="",AH27=""),"",IF(ISERROR(ROUND(AVERAGE(AE27,AF27,AG27,AH27),0)),"",ROUND(AVERAGE(AE27,AF27,AG27,AH27),0))) | AN27: =IF(OR(AJ27="",AK27="",AL27="",AM27=""),"",IF(ISERROR(ROUND(AVERAGE(AJ27,AK27,AL27,AM27),0)),"",ROUND(AVERAGE(AJ27,AK27,AL27,AM27),0))) | AS27: =IF(OR(AO27="",AP27="",AQ27="",AR27=""),"",IF(ISERROR(ROUND(AVERAGE(AO27,AP27,AQ27,AR27),0)),"",ROUND(AVERAGE(AO27,AP27,AQ27,AR27),0))) | AT27: =IF(ISERROR(J27+O27+T27+Y27+AD27+AI27+AN27+AS27)/8,"",(J27+O27+T27+Y27+AD27+AI27+AN27+AS27)/8) -> 0 | AU27: =IF(ISERROR(ROUND(AT27,0)),"",ROUND(AT27,0)) -> 0
B28: FEMALE | J28: =IF(OR(F28="",G28="",H28="",I28=""),"",IF(ISERROR(ROUND(AVERAGE(F28,G28,H28,I28),0)),"",ROUND(AVERAGE(F28,G28,H28,I28),0))) | O28: =IF(OR(K28="",L28="",M28="",N28=""),"",IF(ISERROR(ROUND(AVERAGE(K28,L28,M28,N28),0)),"",ROUND(AVERAGE(K28,L28,M28,N28),0))) | T28: =IF(OR(P28="",Q28="",R28="",S28=""),"",IF(ISERROR(ROUND(AVERAGE(P28,Q28,R28,S28),0)),"",ROUND(AVERAGE(P28,Q28,R28,S28),0))) | Y28: =IF(OR(U28="",V28="",W28="",X28=""),"",IF(ISERROR(ROUND(AVERAGE(U28,V28,W28,X28),0)),"",ROUND(AVERAGE(U28,V28,W28,X28),0))) | AD28: =IF(OR(Z28="",AA28="",AB28="",AC28=""),"",IF(ISERROR(ROUND(AVERAGE(Z28,AA28,AB28,AC28),0)),"",ROUND(AVERAGE(Z28,AA28,AB28,AC28),0))) | AI28: =IF(OR(AE28="",AF28="",AG28="",AH28=""),"",IF(ISERROR(ROUND(AVERAGE(AE28,AF28,AG28,AH28),0)),"",ROUND(AVERAGE(AE28,AF28,AG28,AH28),0))) | AN28: =IF(OR(AJ28="",AK28="",AL28="",AM28=""),"",IF(ISERROR(ROUND(AVERAGE(AJ28,AK28,AL28,AM28),0)),"",ROUND(AVERAGE(AJ28,AK28,AL28,AM28),0))) | AS28: =IF(OR(AO28="",AP28="",AQ28="",AR28=""),"",IF(ISERROR(ROUND(AVERAGE(AO28,AP28,AQ28,AR28),0)),"",ROUND(AVERAGE(AO28,AP28,AQ28,AR28),0))) | AT28: =IF(ISERROR(J28+O28+T28+Y28+AD28+AI28+AN28+AS28)/8,"",(J28+O28+T28+Y28+AD28+AI28+AN28+AS28)/8) -> 0 | AU28: =IF(ISERROR(ROUND(AT28,0)),"",ROUND(AT28,0)) -> 0
A29: 1 | J29: =IF(OR(F29="",G29="",H29="",I29=""),"",IF(ISERROR(ROUND(AVERAGE(F29,G29,H29,I29),0)),"",ROUND(AVERAGE(F29,G29,H29,I29),0))) | O29: =IF(OR(K29="",L29="",M29="",N29=""),"",IF(ISERROR(ROUND(AVERAGE(K29,L29,M29,N29),0)),"",ROUND(AVERAGE(K29,L29,M29,N29),0))) | T29: =IF(OR(P29="",Q29="",R29="",S29=""),"",IF(ISERROR(ROUND(AVERAGE(P29,Q29,R29,S29),0)),"",ROUND(AVERAGE(P29,Q29,R29,S29),0))) | Y29: =IF(OR(U29="",V29="",W29="",X29=""),"",IF(ISERROR(ROUND(AVERAGE(U29,V29,W29,X29),0)),"",ROUND(AVERAGE(U29,V29,W29,X29),0))) | AD29: =IF(OR(Z29="",AA29="",AB29="",AC29=""),"",IF(ISERROR(ROUND(AVERAGE(Z29,AA29,AB29,AC29),0)),"",ROUND(AVERAGE(Z29,AA29,AB29,AC29),0))) | AI29: =IF(OR(AE29="",AF29="",AG29="",AH29=""),"",IF(ISERROR(ROUND(AVERAGE(AE29,AF29,AG29,AH29),0)),"",ROUND(AVERAGE(AE29,AF29,AG29,AH29),0))) | AN29: =IF(OR(AJ29="",AK29="",AL29="",AM29=""),"",IF(ISERROR(ROUND(AVERAGE(AJ29,AK29,AL29,AM29),0)),"",ROUND(AVERAGE(AJ29,AK29,AL29,AM29),0))) | AS29: =IF(OR(AO29="",AP29="",AQ29="",AR29=""),"",IF(ISERROR(ROUND(AVERAGE(AO29,AP29,AQ29,AR29),0)),"",ROUND(AVERAGE(AO29,AP29,AQ29,AR29),0))) | AT29: =IF(ISERROR(J29+O29+T29+Y29+AD29+AI29+AN29+AS29)/8,"",(J29+O29+T29+Y29+AD29+AI29+AN29+AS29)/8) -> 0 | AU29: =IF(ISERROR(ROUND(AT29,0)),"",ROUND(AT29,0)) -> 0
A30: 2 | J30: =IF(OR(F30="",G30="",H30="",I30=""),"",IF(ISERROR(ROUND(AVERAGE(F30,G30,H30,I30),0)),"",ROUND(AVERAGE(F30,G30,H30,I30),0))) | O30: =IF(OR(K30="",L30="",M30="",N30=""),"",IF(ISERROR(ROUND(AVERAGE(K30,L30,M30,N30),0)),"",ROUND(AVERAGE(K30,L30,M30,N30),0))) | T30: =IF(OR(P30="",Q30="",R30="",S30=""),"",IF(ISERROR(ROUND(AVERAGE(P30,Q30,R30,S30),0)),"",ROUND(AVERAGE(P30,Q30,R30,S30),0))) | Y30: =IF(OR(U30="",V30="",W30="",X30=""),"",IF(ISERROR(ROUND(AVERAGE(U30,V30,W30,X30),0)),"",ROUND(AVERAGE(U30,V30,W30,X30),0))) | AD30: =IF(OR(Z30="",AA30="",AB30="",AC30=""),"",IF(ISERROR(ROUND(AVERAGE(Z30,AA30,AB30,AC30),0)),"",ROUND(AVERAGE(Z30,AA30,AB30,AC30),0))) | AI30: =IF(OR(AE30="",AF30="",AG30="",AH30=""),"",IF(ISERROR(ROUND(AVERAGE(AE30,AF30,AG30,AH30),0)),"",ROUND(AVERAGE(AE30,AF30,AG30,AH30),0))) | AN30: =IF(OR(AJ30="",AK30="",AL30="",AM30=""),"",IF(ISERROR(ROUND(AVERAGE(AJ30,AK30,AL30,AM30),0)),"",ROUND(AVERAGE(AJ30,AK30,AL30,AM30),0))) | AS30: =IF(OR(AO30="",AP30="",AQ30="",AR30=""),"",IF(ISERROR(ROUND(AVERAGE(AO30,AP30,AQ30,AR30),0)),"",ROUND(AVERAGE(AO30,AP30,AQ30,AR30),0))) | AT30: =IF(ISERROR(J30+O30+T30+Y30+AD30+AI30+AN30+AS30)/8,"",(J30+O30+T30+Y30+AD30+AI30+AN30+AS30)/8) -> 0 | AU30: =IF(ISERROR(ROUND(AT30,0)),"",ROUND(AT30,0)) -> 0
A31: 3 | J31: =IF(OR(F31="",G31="",H31="",I31=""),"",IF(ISERROR(ROUND(AVERAGE(F31,G31,H31,I31),0)),"",ROUND(AVERAGE(F31,G31,H31,I31),0))) | O31: =IF(OR(K31="",L31="",M31="",N31=""),"",IF(ISERROR(ROUND(AVERAGE(K31,L31,M31,N31),0)),"",ROUND(AVERAGE(K31,L31,M31,N31),0))) | T31: =IF(OR(P31="",Q31="",R31="",S31=""),"",IF(ISERROR(ROUND(AVERAGE(P31,Q31,R31,S31),0)),"",ROUND(AVERAGE(P31,Q31,R31,S31),0))) | Y31: =IF(OR(U31="",V31="",W31="",X31=""),"",IF(ISERROR(ROUND(AVERAGE(U31,V31,W31,X31),0)),"",ROUND(AVERAGE(U31,V31,W31,X31),0))) | AD31: =IF(OR(Z31="",AA31="",AB31="",AC31=""),"",IF(ISERROR(ROUND(AVERAGE(Z31,AA31,AB31,AC31),0)),"",ROUND(AVERAGE(Z31,AA31,AB31,AC31),0))) | AI31: =IF(OR(AE31="",AF31="",AG31="",AH31=""),"",IF(ISERROR(ROUND(AVERAGE(AE31,AF31,AG31,AH31),0)),"",ROUND(AVERAGE(AE31,AF31,AG31,AH31),0))) | AN31: =IF(OR(AJ31="",AK31="",AL31="",AM31=""),"",IF(ISERROR(ROUND(AVERAGE(AJ31,AK31,AL31,AM31),0)),"",ROUND(AVERAGE(AJ31,AK31,AL31,AM31),0))) | AS31: =IF(OR(AO31="",AP31="",AQ31="",AR31=""),"",IF(ISERROR(ROUND(AVERAGE(AO31,AP31,AQ31,AR31),0)),"",ROUND(AVERAGE(AO31,AP31,AQ31,AR31),0))) | AT31: =IF(ISERROR(J31+O31+T31+Y31+AD31+AI31+AN31+AS31)/8,"",(J31+O31+T31+Y31+AD31+AI31+AN31+AS31)/8) -> 0 | AU31: =IF(ISERROR(ROUND(AT31,0)),"",ROUND(AT31,0)) -> 0
A32: 4 | J32: =IF(OR(F32="",G32="",H32="",I32=""),"",IF(ISERROR(ROUND(AVERAGE(F32,G32,H32,I32),0)),"",ROUND(AVERAGE(F32,G32,H32,I32),0))) | O32: =IF(OR(K32="",L32="",M32="",N32=""),"",IF(ISERROR(ROUND(AVERAGE(K32,L32,M32,N32),0)),"",ROUND(AVERAGE(K32,L32,M32,N32),0))) | T32: =IF(OR(P32="",Q32="",R32="",S32=""),"",IF(ISERROR(ROUND(AVERAGE(P32,Q32,R32,S32),0)),"",ROUND(AVERAGE(P32,Q32,R32,S32),0))) | Y32: =IF(OR(U32="",V32="",W32="",X32=""),"",IF(ISERROR(ROUND(AVERAGE(U32,V32,W32,X32),0)),"",ROUND(AVERAGE(U32,V32,W32,X32),0))) | AD32: =IF(OR(Z32="",AA32="",AB32="",AC32=""),"",IF(ISERROR(ROUND(AVERAGE(Z32,AA32,AB32,AC32),0)),"",ROUND(AVERAGE(Z32,AA32,AB32,AC32),0))) | AI32: =IF(OR(AE32="",AF32="",AG32="",AH32=""),"",IF(ISERROR(ROUND(AVERAGE(AE32,AF32,AG32,AH32),0)),"",ROUND(AVERAGE(AE32,AF32,AG32,AH32),0))) | AN32: =IF(OR(AJ32="",AK32="",AL32="",AM32=""),"",IF(ISERROR(ROUND(AVERAGE(AJ32,AK32,AL32,AM32),0)),"",ROUND(AVERAGE(AJ32,AK32,AL32,AM32),0))) | AS32: =IF(OR(AO32="",AP32="",AQ32="",AR32=""),"",IF(ISERROR(ROUND(AVERAGE(AO32,AP32,AQ32,AR32),0)),"",ROUND(AVERAGE(AO32,AP32,AQ32,AR32),0))) | AT32: =IF(ISERROR(J32+O32+T32+Y32+AD32+AI32+AN32+AS32)/8,"",(J32+O32+T32+Y32+AD32+AI32+AN32+AS32)/8) -> 0 | AU32: =IF(ISERROR(ROUND(AT32,0)),"",ROUND(AT32,0)) -> 0
A33: 5 | J33: =IF(OR(F33="",G33="",H33="",I33=""),"",IF(ISERROR(ROUND(AVERAGE(F33,G33,H33,I33),0)),"",ROUND(AVERAGE(F33,G33,H33,I33),0))) | O33: =IF(OR(K33="",L33="",M33="",N33=""),"",IF(ISERROR(ROUND(AVERAGE(K33,L33,M33,N33),0)),"",ROUND(AVERAGE(K33,L33,M33,N33),0))) | T33: =IF(OR(P33="",Q33="",R33="",S33=""),"",IF(ISERROR(ROUND(AVERAGE(P33,Q33,R33,S33),0)),"",ROUND(AVERAGE(P33,Q33,R33,S33),0))) | Y33: =IF(OR(U33="",V33="",W33="",X33=""),"",IF(ISERROR(ROUND(AVERAGE(U33,V33,W33,X33),0)),"",ROUND(AVERAGE(U33,V33,W33,X33),0))) | AD33: =IF(OR(Z33="",AA33="",AB33="",AC33=""),"",IF(ISERROR(ROUND(AVERAGE(Z33,AA33,AB33,AC33),0)),"",ROUND(AVERAGE(Z33,AA33,AB33,AC33),0))) | AI33: =IF(OR(AE33="",AF33="",AG33="",AH33=""),"",IF(ISERROR(ROUND(AVERAGE(AE33,AF33,AG33,AH33),0)),"",ROUND(AVERAGE(AE33,AF33,AG33,AH33),0))) | AN33: =IF(OR(AJ33="",AK33="",AL33="",AM33=""),"",IF(ISERROR(ROUND(AVERAGE(AJ33,AK33,AL33,AM33),0)),"",ROUND(AVERAGE(AJ33,AK33,AL33,AM33),0))) | AS33: =IF(OR(AO33="",AP33="",AQ33="",AR33=""),"",IF(ISERROR(ROUND(AVERAGE(AO33,AP33,AQ33,AR33),0)),"",ROUND(AVERAGE(AO33,AP33,AQ33,AR33),0))) | AT33: =IF(ISERROR(J33+O33+T33+Y33+AD33+AI33+AN33+AS33)/8,"",(J33+O33+T33+Y33+AD33+AI33+AN33+AS33)/8) -> 0 | AU33: =IF(ISERROR(ROUND(AT33,0)),"",ROUND(AT33,0)) -> 0
A34: 6 | J34: =IF(OR(F34="",G34="",H34="",I34=""),"",IF(ISERROR(ROUND(AVERAGE(F34,G34,H34,I34),0)),"",ROUND(AVERAGE(F34,G34,H34,I34),0))) | O34: =IF(OR(K34="",L34="",M34="",N34=""),"",IF(ISERROR(ROUND(AVERAGE(K34,L34,M34,N34),0)),"",ROUND(AVERAGE(K34,L34,M34,N34),0))) | T34: =IF(OR(P34="",Q34="",R34="",S34=""),"",IF(ISERROR(ROUND(AVERAGE(P34,Q34,R34,S34),0)),"",ROUND(AVERAGE(P34,Q34,R34,S34),0))) | Y34: =IF(OR(U34="",V34="",W34="",X34=""),"",IF(ISERROR(ROUND(AVERAGE(U34,V34,W34,X34),0)),"",ROUND(AVERAGE(U34,V34,W34,X34),0))) | AD34: =IF(OR(Z34="",AA34="",AB34="",AC34=""),"",IF(ISERROR(ROUND(AVERAGE(Z34,AA34,AB34,AC34),0)),"",ROUND(AVERAGE(Z34,AA34,AB34,AC34),0))) | AI34: =IF(OR(AE34="",AF34="",AG34="",AH34=""),"",IF(ISERROR(ROUND(AVERAGE(AE34,AF34,AG34,AH34),0)),"",ROUND(AVERAGE(AE34,AF34,AG34,AH34),0))) | AN34: =IF(OR(AJ34="",AK34="",AL34="",AM34=""),"",IF(ISERROR(ROUND(AVERAGE(AJ34,AK34,AL34,AM34),0)),"",ROUND(AVERAGE(AJ34,AK34,AL34,AM34),0))) | AS34: =IF(OR(AO34="",AP34="",AQ34="",AR34=""),"",IF(ISERROR(ROUND(AVERAGE(AO34,AP34,AQ34,AR34),0)),"",ROUND(AVERAGE(AO34,AP34,AQ34,AR34),0))) | AT34: =IF(ISERROR(J34+O34+T34+Y34+AD34+AI34+AN34+AS34)/8,"",(J34+O34+T34+Y34+AD34+AI34+AN34+AS34)/8) -> 0 | AU34: =IF(ISERROR(ROUND(AT34,0)),"",ROUND(AT34,0)) -> 0
